Workbook

Sheet I. Chân Dung KH
A1: CHÂN DUNG KHÁCH HÀNG (PERSONA) – THEO SẢN PHẨM VÀ ĐỊA ĐIỂM
A2: Phân tích chi tiết đối tượng phụ huynh mục tiêu, nỗi đau, insight và messaging phù hợp cho từng cấp học và từng địa điểm
A4: A. PERSONA THEO CẤP HỌC
A5: Cấp học | B5: Tên Persona | C5: Tuổi | D5: Giới tính | E5: Nghề nghiệp | F5: Thu nhập/tháng | G5: Hành vi Online | H5: Kênh tiếp cận chính | I5: Nỗi đau #1 | J5: Nỗi đau #2 | K5: Nỗi đau #3 | L5: Insight mua hàng | M5: Messaging chính | N5: CTA hiệu quả | O5: Objection thường gặp | P5: Cách xử lý Objection
A6: MN (Mầm non) | B6: Chị Lan – Mẹ bỉm sữa | C6: 26-35 | D6: Nữ 85% | E6: Nhân viên VP, kinh doanh nhỏ | F6: 15-30 triệu | G6: Facebook 3h/ngày, Zalo, TikTok, group MN | H6: Meta Ads, Zalo OA, TikTok | I6: Sợ con bị bắt nạt / không an toàn | J6: Thiếu thời gian đưa đón, cần trường gần nhà | K6: Lo giáo viên không tận tâm, thay đổi liên tục | L6: Tin review PH khác > quảng cáo; Quyết định nhanh nếu tour ấn tượng | M6: Môi trường an toàn, camera 24/7, GV tận tâm, gần nhà | N6: Đăng ký tham quan trường MIỄN PHÍ | O6: Học phí cao hơn trường khác | P6: So sánh giá trị: ăn sạch, GV/trẻ tỷ lệ thấp, camera, ngoại khóa
A7: MN (Mầm non) | B7: Anh Tuấn – Ba trẻ quan tâm GD | C7: 30-40 | D7: Nam 15% | E7: Quản lý, kỹ sư, CNTT | F7: 25-50 triệu | G7: Google Search, YouTube review | H7: Google Ads, YouTube | I7: Muốn con phát triển toàn diện sớm | J7: Lo trường không có chương trình song ngữ tốt | K7: Không biết trường nào uy tín gần nhà | L7: So sánh kỹ trên Google trước khi tour | M7: Song ngữ từ 3 tuổi, chương trình STEAM | N7: Xem chi tiết chương trình học | O7: Muốn chờ vợ quyết định | P7: Mời cả 2 PH cùng tour, tặng ưu đãi
A8: TH (Tiểu học) | B8: Chị Mai – PH lớp 1 lo lắng | C8: 30-42 | D8: Nữ 75% | E8: Nhân viên, giáo viên, kinh doanh | F8: 20-40 triệu | G8: Facebook, Zalo group, tìm Google | H8: Meta Ads, Google Search, Zalo | I8: Sợ con không theo kịp chương trình | J8: Lo trường tư "nhẹ" hơn trường công | K8: Áp lực tiếng Anh – con chưa có nền tảng | L8: Tham khảo 3-5 trường trước khi chọn; Tour 2 lần | M8: Lộ trình tiếng Anh rõ ràng, sĩ số nhỏ 25-30, GV theo sát | N8: Đặt lịch tham quan + tư vấn 1-1 | O8: Trường công miễn phí mà cũng tốt | P8: Sĩ số 50 vs 25, không ngoại khóa, GV không theo sát
A9: TH (Tiểu học) | B9: Anh Hùng – PH chuyển con từ công sang tư | C9: 35-45 | D9: Nam 25% | E9: Chủ DN nhỏ, quản lý | F9: 30-60 triệu | G9: Google, Facebook, hỏi bạn bè | H9: Google Ads, Remarketing | I9: Con đang học công nhưng không phát triển | J9: Muốn môi trường tốt hơn, ít bạo lực | K9: Lo con không thích nghi khi chuyển | L9: Quyết định nhanh khi thấy cơ sở vật chất tốt | M9: Chuyển cấp linh hoạt, hỗ trợ hòa nhập, CSVC hiện đại | N9: Đăng ký chuyển trường – Hỗ trợ hồ sơ nhanh | O9: Con đã quen trường cũ | P9: Hỗ trợ hòa nhập 2 tuần, buddy system
A10: THCS (Cấp 2) | B10: Chị Hoa – PH lớp 6 giai đoạn bản lề | C10: 35-48 | D10: Nữ 65% | E10: Nhân viên, công chức, kinh doanh | F10: 25-50 triệu | G10: Facebook, Google, Webinar, Forum | H10: Meta Ads, Google Ads, Webinar | I10: Sợ con sa sút vì giai đoạn dậy thì | J10: Lo trường không theo sát tâm lý HS | K10: Áp lực kết quả thi cuối cấp | L10: Tham gia webinar trước khi tour; Cần dữ liệu đầu ra | M10: Theo sát HS giai đoạn bản lề, GV chủ nhiệm tâm huyết | N10: Đăng ký webinar: Lộ trình con tôi sau lớp 5 | O10: Học phí THCS cao hơn TH nhiều | P10: ROI dài hạn: nền tảng cho lớp 10, đại học
A11: THCS (Cấp 2) | B11: Anh Minh – PH muốn con có lộ trình rõ | C11: 38-50 | D11: Nam 35% | E11: Quản lý, chuyên gia, DN | F11: 40-80 triệu | G11: Google Search, YouTube, LinkedIn | H11: Google Ads, YouTube, Webinar | I11: Muốn con có định hướng nghề nghiệp sớm | J11: Lo trường chỉ dạy lý thuyết, thiếu thực hành | K11: Muốn chương trình quốc tế/song ngữ chuẩn | L11: So sánh đầu ra, tỷ lệ đỗ THPT top, chương trình quốc tế | M11: Lộ trình 6→12 rõ ràng, chương trình Cambridge/IB option | N11: Xem lộ trình đào tạo 7 năm | O11: Trường xa nhà | P11: Xe đưa đón, kế hoạch bán trú
A12: THPT (Cấp 3) | B12: Chị Thảo – PH lớp 10 áp lực thi | C12: 38-52 | D12: Nữ 60% | E12: Nhân viên, giáo viên, kinh doanh | F12: 30-60 triệu | G12: Facebook, Google, Webinar, tìm học bổng | H12: Google Ads, Meta Ads, Webinar | I12: Lo con không đỗ trường công top | J12: Áp lực tài chính: học phí THPT tư cao | K12: Lo con không vào được đại học tốt | L12: Quyết định theo học bổng + đầu ra đại học | M12: Học bổng lên đến 100%, đầu ra ĐH top, tỷ lệ đỗ ĐH 95%+ | N12: Đăng ký thi học bổng lớp 10 | O12: Trường tư chất lượng không bằng chuyên | P12: Data đầu ra: % ĐH top, học bổng du học, IELTS
A13: THPT (Cấp 3) | B13: Anh Đức – PH chuyển trường lớp 10-11 | C13: 40-55 | D13: Nam 40% | E13: Chủ DN, quản lý cấp cao | F13: 50-100+ triệu | G13: Google Search, YouTube, referral | H13: Google Ads, Remarketing | I13: Con đang học trường không phù hợp | J13: Muốn môi trường quốc tế + du học pathway | K13: Cần chuyển nhanh, ít gián đoạn | L13: Quyết định rất nhanh khi thấy phù hợp | M13: Chuyển trường linh hoạt, nhận hồ sơ quanh năm, pathway du học | N13: Liên hệ tư vấn chuyển trường 24h | O13: Sợ con mất bạn bè | P13: Chương trình hòa nhập, buddy system, câu lạc bộ
A16: B. NỖI ĐAU KHÁCH HÀNG THEO ĐỊA ĐIỂM
A17: Địa điểm | B17: Tên cũ (trước sáp nhập) | C17: Tên mới (hiện tại) | D17: Cấp học | E17: Đặc điểm PH khu vực | F17: Nỗi đau đặc thù #1 | G17: Nỗi đau đặc thù #2 | H17: Nỗi đau đặc thù #3 | I17: Messaging phù hợp | J17: Kênh ưu tiên | K17: Đối thủ chính | L17: Lợi thế VA tại đây
A18: MN VA Gò Vấp | B18: Q. Gò Vấp, TP.HCM | C18: Q. Gò Vấp, TP.HCM | D18: MN | E18: Thu nhập trung bình-khá, đông dân, nhiều gia đình trẻ | F18: Trường MN quá tải, thiếu chỗ gửi an toàn | G18: Giao thông kẹt, cần trường gần nhà | H18: Lo bạo lực, thiếu camera giám sát | I18: An toàn #1, gần nhà, camera 24/7 | J18: Meta Ads, Zalo OA | K18: MN Sài Gòn, MN Sao Mai | L18: Flagship, CSVC mới, GV ổn định
A19: MN Nhân Lễ | B19: H. Cần Giuộc, Long An | C19: TX. Cần Giuộc, Tây Ninh | D19: MN | E19: Thu nhập trung bình, vùng KDC mới, ít lựa chọn | F19: Rất ít trường tư chất lượng trong KDC | G19: PH làm ở KCN, cần trường bán trú tốt | H19: Lo con thiếu ngoại ngữ vùng tỉnh | I19: Trường chuẩn quốc tế ngay KDC, bán trú chu đáo | J19: Zalo OA, Facebook local | K19: MN công lập địa phương | L19: Duy nhất trường tư chất lượng trong KDC
A20: MN Thái Sơn | B20: H. Cần Giuộc, Long An | C20: TX. Cần Giuộc, Tây Ninh | D20: MN+TH | E20: PH KDC Thái Sơn, thu nhập khá, mới về định cư | F20: Thiếu trường tốt gần KDC mới | G20: Muốn con có bạn bè trong khu | H20: Lo chất lượng GD vùng mới phát triển | I20: Ngay trong KDC, không cần đưa đón xa | J20: Zalo OA, Facebook group KDC | K20: MN công, MN tư nhỏ lẻ | L20: Nằm ngay trong KDC, liên cấp MN+TH
A21: MN Mekong Xanh | B21: TP. Rạch Giá, Kiên Giang | C21: TP. Rạch Giá, An Giang | D21: MN+TH | E21: PH KĐT mới, thu nhập khá, nhiều công chức/DN | F21: Ít lựa chọn trường tư trong KĐT | G21: Muốn chương trình song ngữ mà vùng tỉnh không có | H21: Lo con thua thiệt so với TP.HCM | I21: Song ngữ chuẩn TP.HCM ngay tại tỉnh | J21: Zalo OA, Facebook local, Google local | K21: Trường công lập, TT Anh ngữ | L21: Chuẩn TP.HCM, liên cấp, KĐT cao cấp
A22: TH VA Gò Vấp | B22: Q. Gò Vấp, TP.HCM | C22: Q. Gò Vấp, TP.HCM | D22: TH | E22: PH trung lưu-khá, so sánh kỹ nhiều trường | F22: Quá nhiều lựa chọn, không biết trường nào tốt | G22: Lo tiếng Anh không đủ mạnh so với international school | H22: Sĩ số lớp quá đông ở trường công | I22: Sĩ số 25, lộ trình tiếng Anh có chứng chỉ, GV 1-1 | J22: Meta Ads, Google Search | K22: TH Việt Úc, TH iSchool, TH FPT | L22: Học phí hợp lý hơn international, vẫn song ngữ chuẩn
A23: TH VA Bình Tân | B23: Q. Bình Tân, TP.HCM | C23: Q. Bình Tân, TP.HCM | D23: TH | E23: PH thu nhập trung bình, khu đông dân, công nhân + KD nhỏ | F23: Rất ít trường tư chất lượng khu vực Bình Tân | G23: Lo an ninh khu vực, muốn trường khép kín | H23: Giá phải hợp lý với thu nhập | I23: An toàn, khép kín, học phí phù hợp, bán trú tốt | J23: Meta Ads, Zalo local | K23: TH Bình Tân, TH Phước Kiểng | L23: Duy nhất trường tư song ngữ quy mô tại BT
A24: TH Thái Sơn | B24: H. Cần Giuộc, Long An | C24: TX. Cần Giuộc, Tây Ninh | D24: TH | E24: PH KDC Thái Sơn, muốn con học tại chỗ | F24: Phải đi xa để học trường tốt | G24: Lo con mệt vì di chuyển hàng ngày | H24: Chương trình tỉnh yếu hơn TP | I24: Chuẩn TP.HCM ngay KDC, không cần đi xa | J24: Zalo, Facebook local | K24: TH công lập xã | L24: Liên cấp, ngay trong KDC
A25: TH Mekong Xanh | B25: TP. Rạch Giá, Kiên Giang | C25: TP. Rạch Giá, An Giang | D25: TH | E25: PH KĐT, muốn con có nền tảng tốt | F25: Không có trường tư song ngữ tại TP Rạch Giá | G25: Muốn con thi vào trường tốt sau này | H25: Lo GV giỏi không về tỉnh dạy | I25: GV từ TP.HCM, chương trình chuẩn quốc gia + song ngữ | J25: Zalo, Facebook, Google local | K25: TH công, TT Anh ngữ | L25: Duy nhất TH tư song ngữ quy mô
A26: THCS VA Gò Vấp | B26: Q. Gò Vấp, TP.HCM | C26: Q. Gò Vấp, TP.HCM | D26: THCS | E26: PH lo lắng giai đoạn dậy thì, cần theo sát | F26: Trường công THCS sĩ số 45-50, GV không theo sát | G26: Lo con sa sút vì bạn bè tiêu cực | H26: Áp lực thi THPT cạnh tranh | I26: Sĩ số nhỏ, GV chủ nhiệm theo sát, lộ trình 6→12 | J26: Google Ads, Meta, Webinar | K26: THCS Việt Úc, THCS iSchool | L26: Liên cấp THCS-THPT, không cần thi chuyển
A27: THPT VA Gò Vấp | B27: Q. Gò Vấp, TP.HCM | C27: Q. Gò Vấp, TP.HCM | D27: THPT | E27: PH áp lực thi lớp 10, tìm giải pháp B nếu rớt công | F27: Con không đỗ trường công top → hoang mang | G27: Học phí THPT tư cao, lo tài chính | H27: Lo đầu ra đại học không tốt bằng trường chuyên | I27: Học bổng 100%, đầu ra ĐH 95%+, pathway du học | J27: Google Ads, Meta, Webinar | K27: THPT Nguyễn Khuyến, THPT Trương Vĩnh Ký | L27: Học bổng lớn, lộ trình đa dạng, tỷ lệ ĐH cao
A30: C. HÀNH TRÌNH KHÁCH HÀNG (CUSTOMER JOURNEY) THEO CẤP
A31: Giai đoạn | B31: Awareness | C31: Consideration | D31: Decision | E31: Tour/Visit | F31: Enrollment | G31: Advocacy
A32: MN | B32: Thấy ads FB/TikTok → nghe PH review → tìm Google | C32: So sánh 2-3 trường → đọc review → hỏi group | D32: Gọi hotline / Zalo → Hỏi học phí → Book tour | E32: Tour campus → gặp GV → xem phòng học → lunch trial | F32: Nộp hồ sơ → đóng cọc → nhận thông báo | G32: Review Google → giới thiệu bạn → share FB
A33: TH | B33: Tìm Google "trường TH song ngữ" → thấy ads Meta | C33: So sánh 3-5 trường → tour 2 lần → hỏi PH hiện tại | D33: Webinar/Open Day → tư vấn 1-1 → nhận ưu đãi | E33: Tour chi tiết → ngồi lớp thử → gặp GV chủ nhiệm | F33: Thi đầu vào (nếu có) → nộp hồ sơ → đóng phí | G33: Review → referral program → PH ambassador
A34: THCS | B34: Webinar "chuyển cấp" → Google "THCS tốt GV" → FB ads | C34: So sánh đầu ra → xem chương trình → hỏi alumni PH | D34: Tư vấn riêng → xem lộ trình 6→12 → học bổng | E34: Tour + ngồi lớp + gặp HS hiện tại + GV chủ nhiệm | F34: Nộp hồ sơ → phỏng vấn → đóng cọc | G34: PH chia sẻ experience → alumni success story
A35: THPT | B35: Google "tuyển sinh lớp 10" → Webinar → FB/TikTok | C35: So sánh vs công → check đầu ra ĐH → học bổng | D35: Thi học bổng → tư vấn chuyên sâu → financial plan | E35: Tour VIP → gặp BGH → xem lab/thư viện/CLB | F35: Thi tuyển/xét tuyển → nhận kết quả → enrollment | G35: Đầu ra ĐH → alumni network → PH referral
A38: HÀNH TRÌNH QUYẾT ĐỊNH CỦA PHỤ HUYNH — CUSTOMER JOURNEY MAP
A39: Cấp Học | B39: Giai Đoạn | C39: Trigger/Channels | D39: Content Cần | E39: Funnel Page | F39: Ads Hiện | G39: CRM Action | H39: KPI
A40: MN | B40: Nhận Thức | C40: Search "trường MN tốt", FB feed, Referral | D40: Blog: Chọn trường như thế nào | E40: forms.truongvietanh.com/awareness-mn | F40: Search Ads (KW: trường MN) | G40: Tag: Awareness | H40: CTR 2%
A41: MN | B41: Tìm Hiểu | C41: Visit website, compare 3 trường | D41: So sánh, review, chứng chỉ | E41: forms.truongvietanh.com/consideration-mn | F41: Remarketing display ads | G41: Tag: Consideration | H41: Time on site 3+min
A42: MN | B42: Tham Quan | C42: Đăng ký tour, gặp hiệu trưởng | D42: Virtual tour, bảng giá, Q&A | E42: forms.truongvietanh.com/tour-mn | F42: Zalo OA message | G42: Event: Tour scheduled | H42: Attendance 85%
A43: MN | B43: Quyết Định | C43: Gặp phụ huynh khác, quyết định | D43: Hồ sơ ghi danh, học phí | E43: forms.truongvietanh.com/enroll-mn | F43: Conversion ads | G43: Create: Lead in CRM | H43: Conversion 15%
A44: MN | B44: Referral | C44: Khuyên bạn bè, review | D44: Referral program info, incentive | E44: forms.truongvietanh.com/refer-mn | F44: None | G44: Tag: Enrolled + Referrer | H44: Referral rate 10%
A45: TH | B45: Nhận Thức | C45: Google search, Facebook, TikTok | D45: Blog: Tại sao TH quốc tế | E45: forms.truongvietanh.com/awareness-th | F45: Video ads + Search ads | G45: Tag: Awareness | H45: Video views 5k+
A46: TH | B46: Tìm Hiểu | C46: Video review, website | D46: Chương trình giáo dục, giáo viên | E46: forms.truongvietanh.com/consideration-th | F46: Story ads, carousel ads | G46: Tag: Consideration | H46: Engagement 5%
A47: TH | B47: Tham Quan | C47: Lớp học trực tiếp, gặp cô | D47: Lịch học, hoạt động ngoài giờ | E47: forms.truongvietanh.com/tour-th | F47: Zalo + Email reminder | G47: Event: Tour scheduled | H47: Tour completed 90%
...

Sheet 0. Dashboard
B1: 🎯 DASHBOARD ĐIỀU HÀNH – KẾ HOẠCH TUYỂN SINH VIỆT ANH 2026
B2: Giai đoạn: 26/03/2026 – 30/09/2026 | Tổng ngân sách: 13 tỷ đồng | Mục tiêu: 1,300 học sinh
B4: 📊 KPI TỔNG QUAN (tự động liên kết từ các sheet)
B5: Chỉ số | C5: Mục tiêu | D5: Thực tế MTD | E5: Vs Target | F5: Trạng thái | G5: Nguồn dữ liệu | H5: Sheet liên kết
B6: 🏫 Nhập học tích lũy | C6: ='1. Input'!B5 -> 1300 | D6: 0 | E6: =IF(C6>0,D6/C6,0) -> 0 | F6: → Nhập tay | G6: 1. Input | H6: Nhập tay từ CRM
B7: 🎯 School Tour tích lũy | C7: ='4. Funnel'!D3 -> 0 | D7: 0 | E7: =IF(C7>0,D7/C7,0) -> 0 | F7: → Nhập tay | G7: 4. Funnel | H7: Nhập tay từ GHL
B8: 📥 Leads tích lũy | C8: ='4. Funnel'!D4 -> 0 | D8: 0 | E8: =IF(C8>0,D8/C8,0) -> 0 | F8: → Nhập tay | G8: 4. Funnel | H8: Nhập tay từ GHL
B9: 💰 Chi phí Paid Media | C9: ='2. Paid Media'!C10 -> 425000000 | D9: 0 | E9: =IF(C9>0,D9/C9,0) -> 0 | F9: → Nhập tay | G9: 2. Paid Media | H9: Birch / Ads Manager
B10: 📊 CPL trung bình | C10: 200000 | D10: 0 | E10: =IF(C10>0,D10/C10,0) -> 0 | F10: → Nhập tay | G10: 14. Weekly Battleplan | H10: Nhập tay tuần
B11: 🏃 Lead→Tour rate | C11: 0.3 | D11: 0 | E11: =IF(C11>0,D11/C11,0) -> 0 | F11: → Nhập tay | G11: 4. Funnel | H11: Tính từ GHL
B12: ✅ Tour→Nhập học rate | C12: 0.35 | D12: 0 | E12: =IF(C12>0,D12/C12,0) -> 0 | F12: → Nhập tay | G12: 4. Funnel | H12: Tính từ GHL
B13: ⚡ Response <5 min | C13: 0.85 | D13: 0 | E13: =IF(C13>0,D13/C13,0) -> 0 | F13: → Nhập tay | G13: 14. Weekly Battleplan | H13: Nhập tay tuần
B15: 💰 NGÂN SÁCH PAID MEDIA THEO KÊNH (liên kết 2. Paid Media)
B16: Kênh | C16: % Mix | D16: Ngân sách | E16: Vai trò | F16: CPL Mục tiêu | G16: Quản lý | H16: Ghi chú
B17: Meta / Facebook + Instagram | C17: 0.38 | D17: 3230000000 | E17: Demand + lead local | F17: 120000 | G17: Birch + GHL | H17: Kênh chủ lực
B18: Google Search | C18: 0.18 | D18: 1530000000 | E18: Intent-based | F18: 180000 | G18: Birch | H18: THCS/THPT
B19: Google Display / YouTube | C19: 0.07 | D19: 595000000 | E19: Phủ + video | F19: N/A | G19: Birch | H19: Testimonial
B20: TikTok Ads | C20: 0.1 | D20: 850000000 | E20: Video social proof | F20: 90000 | G20: Birch + GHL | H20: 100 video
B21: Zalo Ads + OA | C21: 0.07 | D21: 595000000 | E21: Nurture local | F21: 80000 | G21: GHL | H21: K12 local
B22: Webinar Ads | C22: 0.05 | D22: 425000000 | E22: Webinar lộ trình | F22: 50000 | G22: Meta + GHL | H22: THCS/THPT
B23: Remarketing đa nền tảng | C23: 0.12 | D23: 1020000000 | E23: Đuổi lại khách | F23: 150000 | G23: Birch | H23: 12%
B24: Local SEO / GMB | C24: 0.05 | D24: 425000000 | E24: Local presence | F24: N/A | G24: Manual + GHL | H24: 8 địa điểm
B25: TỔNG PAID MEDIA | C25: 1.02 | D25: 8670000000
B27: 🏫 PHÂN BỔ THEO CƠ SỞ (liên kết 3. Master Table)
B28: Cơ sở | C28: Cấp | D28: HS Mục tiêu | E28: CAC | F28: Meta (đ) | G28: G.Search (đ) | H28: TikTok (đ) | I28: Zalo (đ)
B29: MN VA Gò Vấp | C29: MN | D29: 200 | E29: 0.85 | F29: 405838877 | G29: 192239468 | H29: 106799704 | I29: 74759793
B30: MN Nhân Lễ | C30: MN | D30: 60 | E30: 0.85 | F30: 121751663 | G30: 57671840 | H30: 32039911 | I30: 22427938
B31: MN Thái Sơn | C31: MN | D31: 60 | E31: 0.85 | F31: 121751663 | G31: 57671840 | H31: 32039911 | I31: 22427938
B32: MN Mekong Xanh | C32: MN | D32: 60 | E32: 0.85 | F32: 121751663 | G32: 57671840 | H32: 32039911 | I32: 22427938
B33: TH VA Gò Vấp | C33: TH | D33: 150 | E33: 1 | F33: 358093126 | G33: 169623060 | H33: 94235033 | I33: 65964523
B34: TH VA Bình Tân | C34: TH | D34: 150 | E34: 1 | F34: 358093126 | G34: 169623060 | H34: 94235033 | I34: 65964523
B35: TH Thái Sơn | C35: TH | D35: 60 | E35: 1 | F35: 143237251 | G35: 67849224 | H35: 37694013 | I35: 26385809
B36: TH Mekong Xanh | C36: TH | D36: 60 | E36: 1 | F36: 143237251 | G36: 67849224 | H36: 37694013 | I36: 26385809
B37: THCS VA Gò Vấp | C37: THCS | D37: 200 | E37: 1.2 | F37: 572949002 | G37: 271396896 | H37: 150776053 | I37: 105543237
B38: THPT VA Gò Vấp | C38: THPT | D38: 200 | E38: 1.35 | F38: 644567627 | G38: 305321508 | H38: 169623060 | I38: 118736142
B39: Brand hệ thống | C39: Chung | D39: 100 | E39: 1 | F39: 238728751 | G39: 113082040 | H39: 62823356 | I39: 43976349
B41: 🗂️ NAVIGATOR – DANH SÁCH CÁC SHEET (Click để xem)
B42: # | C42: Tên Sheet | D42: Mô tả | E42: Dùng cho | F42: Cập nhật | G42: Tần suất | H42: Liên kết đến
B43: 1 | C43: 1. Input | D43: Thông số đầu vào toàn kế hoạch | E43: Ban điều hành | F43: 26/03 | G43: Đầu mùa | H43: Master Table, Funnel
B44: 2 | C44: 2. Paid Media | D44: Mix kênh, ngân sách, KPI mỗi kênh | E44: Marketing Lead | F44: Hàng tháng | G44: Tháng | H44: Master Table
...

Sheet 1. Input
A1: INPUT & ĐIỀU KHIỂN – BẢN V5 (BỎ PHÚ NHUẬN, CẬP NHẬT ĐỊA GIỚI)
A2: ⚠️ Phú Nhuận ĐÃ BỎ. Ngân sách phân bổ lại cho các cơ sở còn lại. Cần Giuộc → Tây Ninh. Rạch Giá → An Giang.
A3: Hạng mục | B3: Giá trị | C3: Đơn vị | D3: Ghi chú
A4: Tổng ngân sách | B4: 13000000000 | C4: đ | D4: 13 tỷ
A5: Mục tiêu nhập học | B5: 1300 | C5: HS | D5: Không còn Phú Nhuận → phân bổ lại
A6: NC → Lead | B6: 0.2 | C6: % | D6: Benchmark K12: 18-25%
A7: Lead → School Tour | B7: 0.3 | C7: % | D7: SLA < 5 phút + GHL automation
A8: Tour → Nhập học | B8: 0.35 | C8: % | D8: Thực tế K12 VN
A9: CRM / GoHighLevel | B9: 200000000 | C9: đ | D9: GHL + Zalo + SMS + landing
A10: School Tour / Open Day / Event | B10: 800000000 | C10: đ | D10: Điểm chuyển đổi #1
A11: Nhân sự Sales | B11: 800000000 | C11: đ | D11: Lương + KPI + hoa hồng
A12: Content / Brand / Sales Enablement | B12: 700000000 | C12: đ | D12: Kho sẵn + creative mới
A13: Nhân sự Marketing (5 người × 6T) | B13: 450000000 | C13: đ | D13: 5 người × 6 tháng × 15 triệu
A14: Học bổng / Promotion | B14: 1000000000 | C14: đ | D14: Kích hoạt quyết định
A15: Paid Media | B15: 8500000000 | C15: đ | D15: 65.4% tổng NS
A16: Training / QA / Data / Mystery call | B16: 550000000 | C16: đ | D16: 100+100+200+150 triệu
A18: KIỂM TRA | B18: =SUM(B9:B16) -> 13000000000
A19: Chênh lệch | B19: =B4-B18 -> 0
A20: Trạng thái | B20: =IF(ABS(B19)<1000,"✅ Khớp 13 tỷ","❌ LỆCH") -> ✅ Khớp 13 tỷ
A22: CHI TIẾT BỔ SUNG
A23: Số cơ sở | B23: 6 | C23: cơ sở | D23: Bỏ Phú Nhuận, còn 6 cơ sở hoạt động
A24: Số cấp học | B24: 4 | C24: cấp | D24: MN, TH, THCS, THPT
A25: Số LP cần tạo | B25: 8 | C25: trang | D25: 1 LP/campus + 1 webinar + 1 tỉnh MN + 1 tỉnh TH
A26: Số pipeline GHL | B26: 4 | C26: pipeline | D26: MN, TH, THCS, THPT
A27: Thời gian chiến dịch | B27: 7 | C27: tháng | D27: 26/03 - 30/09/2026
A28: Số tuần tác chiến | B28: 28 | C28: tuần | D28: Tuần 1 (26/03) → Tuần 28 (30/09)
A29: Số nhân sự Marketing | B29: 5 | C29: người | D29: PM×1, Content×2, Performance×1, CRM×1
A30: Số nhân sự Sales | B30: 6 | C30: người | D30: 1 Sales Lead + 5 Tư vấn viên (round-robin)
A31: Kho content sẵn có | B31: 2000 | C31: bài | D31: Ảnh+video+bài viết kho cũ
A32: Video testimonial | B32: 100 | C32: video | D32: Kho 100 video PH+HS+GV sẵn sàng
A33: Webinar planned | B33: 8 | C33: buổi | D33: 6 chính + 2 bổ sung
A34: Open Day planned | B34: 2 | C34: sự kiện | D34: Tháng 5 + Tháng 6
A35: Lead response SLA | B35: 5 | C35: phút | D35: Gọi lại trong 5 phút, mục tiêu 85%
A36: Benchmark NC→Lead | B36: 18-25% | C36: % | D36: K12 VN trung bình
A37: Benchmark Lead→Tour | B37: 25-35% | C37: % | D37: Cần SLA tốt + GHL automation
A38: Benchmark Tour→Enroll | B38: 30-40% | C38: % | D38: Phụ thuộc tour quality + follow-up
A40: DANH SÁCH CƠ SỞ (ĐỊA GIỚI MỚI + CŨ)
A41: STT | B41: Tên cơ sở | C41: Cấp | D41: Địa chỉ | E41: Khu vực mới | F41: Khu vực cũ (trước sáp nhập) | G41: Hotline
A42: 1 | B42: MN VA Gò Vấp | C42: MN | D42: 573 Đ. Lê Đức Thọ, P. An Hội Tây | E42: Q. Gò Vấp, TP.HCM | F42: Q. Gò Vấp, TP.HCM (không đổi) | G42: 0916 961 409
A43: 2 | B43: MN Nhân Lễ | C43: MN | D43: 22 Đường D2, KDC Cần Giuộc | E43: TX. Cần Giuộc, tỉnh Tây Ninh | F43: H. Cần Giuộc, tỉnh Long An | G43: 0916 961 409
...

Sheet 2. Paid Media
A1: MIX KÊNH PAID MEDIA – 8.5 TỶ (TÁCH SEARCH/DISPLAY, KHÔNG CÓ PHÚ NHUẬN)
A2: Kênh | B2: % Mix | C2: Ngân sách | D2: Vai trò | E2: KPI | F2: CPL mục tiêu | G2: Quản lý bởi | H2: Ghi chú
A3: Meta / Facebook + Instagram | B3: 0.38 | C3: =B3*'1. Input'!B15 -> 3230000000 | D3: Demand + lead local | E3: CPL, Volume | F3: 120000 | G3: Birch + GHL | H3: Kênh chủ lực
A4: Google Search (TÁCH RIÊNG) | B4: 0.18 | C4: =B4*'1. Input'!B15 -> 1530000000 | D4: Intent-based | E4: CPC, Quality | F4: 180000 | G4: Birch | H4: Đo riêng THCS/THPT
A5: Google Display / YouTube | B5: 0.07 | C5: =B5*'1. Input'!B15 -> 595000000 | D5: Phủ + video | E5: CPM, View | G5: Birch | H5: Testimonial 15-30s
A6: TikTok Ads | B6: 0.1 | C6: =B6*'1. Input'!B15 -> 850000000 | D6: Video social proof | E6: CPV, Lead | F6: 90000 | G6: Birch + GHL | H6: 100 video = vàng
A7: Zalo Ads + OA | B7: 0.07 | C7: =B7*'1. Input'!B15 -> 595000000 | D7: Nurture local | E7: Open, CTR | F7: 80000 | G7: GoHighLevel | H7: Hidden champion K12
A8: Webinar Ads (THCS/THPT) | B8: 0.05 | C8: =B8*'1. Input'!B15 -> 425000000 | D8: Webinar lộ trình | E8: Đăng ký | F8: 50000 | G8: Meta + GHL | H8: KHÔNG cho MN/TH
A9: Remarketing đa nền tảng | B9: 0.12 | C9: =B9*'1. Input'!B15 -> 1020000000 | D9: Đuổi lại khách | E9: ROAS, Conv | F9: 150000 | G9: Birch | H9: Giảm 15%→12%
A10: Local SEO / Google Business | B10: 0.05 | C10: =B10*'1. Input'!B15 -> 425000000 | D10: Local presence | E10: Map, Clicks | G10: Manual + GHL | H10: 8 địa điểm
A11: TỔNG | B11: =SUM(B3:B10) -> 1.02 | C11: =SUM(C3:C10) -> 8670000000
A13: NGÂN SÁCH PAID MEDIA THEO THÁNG
A14: Kênh | B14: T4 (12%) | C14: T5 (24%) | D14: T6 (28%) | E14: T7 (24%) | F14: T8 (8%) | G14: T9 (2%) | H14: Tổng 7 tháng
A15: Meta / FB+IG | B15: =0.12*C3 -> 387600000 | C15: =0.24*C3 -> 775200000 | D15: =0.28*C3 -> 904400000 | E15: =0.24*C3 -> 775200000 | F15: =0.08*C3 -> 258400000 | G15: =0.02*C3 -> 64600000 | H15: =SUM(B15:G15) -> 3165400000
A16: Google Search | B16: =0.12*C4 -> 183600000 | C16: =0.24*C4 -> 367200000 | D16: =0.28*C4 -> 428400000 | E16: =0.24*C4 -> 367200000 | F16: =0.08*C4 -> 122400000 | G16: =0.02*C4 -> 30600000 | H16: =SUM(B16:G16) -> 1499400000
A17: Google Display/YT | B17: =0.12*C5 -> 71400000 | C17: =0.24*C5 -> 142800000 | D17: =0.28*C5 -> 166600000 | E17: =0.24*C5 -> 142800000 | F17: =0.08*C5 -> 47600000 | G17: =0.02*C5 -> 11900000 | H17: =SUM(B17:G17) -> 583100000
A18: TikTok Ads | B18: =0.12*C6 -> 102000000 | C18: =0.24*C6 -> 204000000 | D18: =0.28*C6 -> 238000000 | E18: =0.24*C6 -> 204000000 | F18: =0.08*C6 -> 68000000 | G18: =0.02*C6 -> 17000000 | H18: =SUM(B18:G18) -> 833000000
A19: Zalo Ads+OA | B19: =0.12*C7 -> 71400000 | C19: =0.24*C7 -> 142800000 | D19: =0.28*C7 -> 166600000 | E19: =0.24*C7 -> 142800000 | F19: =0.08*C7 -> 47600000 | G19: =0.02*C7 -> 11900000 | H19: =SUM(B19:G19) -> 583100000
A20: Webinar Ads | B20: =0.12*C8 -> 51000000 | C20: =0.24*C8 -> 102000000 | D20: =0.28*C8 -> 119000000 | E20: =0.24*C8 -> 102000000 | F20: =0.08*C8 -> 34000000 | G20: =0.02*C8 -> 8500000 | H20: =SUM(B20:G20) -> 416500000
A21: Remarketing | B21: =0.12*C9 -> 122400000 | C21: =0.24*C9 -> 244800000 | D21: =0.28*C9 -> 285600000 | E21: =0.24*C9 -> 244800000 | F21: =0.08*C9 -> 81600000 | G21: =0.02*C9 -> 20400000 | H21: =SUM(B21:G21) -> 999600000
A22: Local SEO/GMB | B22: =0.12*C10 -> 51000000 | C22: =0.24*C10 -> 102000000 | D22: =0.28*C10 -> 119000000 | E22: =0.24*C10 -> 102000000 | F22: =0.08*C10 -> 34000000 | G22: =0.02*C10 -> 8500000 | H22: =SUM(B22:G22) -> 416500000
A24: CHI TIẾT VAI TRÒ TỪNG KÊNH
A25: Kênh | B25: Vai trò trong funnel | C25: Giai đoạn KH | D25: Resource cần | E25: Daily operations | F25: Weekly optimization | G25: Tool chính
A26: Meta Ads | B26: Demand generation + Lead local + Social proof | C26: Awareness → Consideration | D26: 30+ creative (image+video), 12 audiences | E26: Check CPL, scale/pause, creative refresh | F26: A/B test creative, audience expansion, budget realloc | G26: Meta Ads Manager + Birch
A27: Google Search | B27: Intent-based capture + Brand defense | C27: Consideration → Decision | D27: 20 campaigns, 200+ keywords, 15 RSA | E27: Search terms review, bid adjust, QS check | F27: Negative KW update, RSA test, campaign restructure | G27: Google Ads + Birch
A28: Google Display/YT | B28: Awareness phủ + Video retarget | C28: Awareness + Remarketing | D28: 5 display banners, 3 video 15-30s | E28: Check CPM, placement exclusion | F28: Placement review, video performance | G28: Google Ads + Birch
A29: TikTok Ads | B29: Video social proof + Gen Z/Millennial reach | C29: Awareness → Lead | D29: 100 video kho sẵn, 5 new/tháng | E29: Check CPV, engagement, 3s retention | F29: Video performance ranking, upload new | G29: TikTok Ads + Birch
A30: Zalo Ads+OA | B30: Local nurture + Broadcast + Remarketing | C30: Consideration → Decision | D30: 8 broadcast templates, 4 ad creatives | E30: Check OA messages, broadcast schedule | F30: Segment refresh, broadcast content planning | G30: Zalo Ads + GHL
A31: Webinar Ads | B31: Education + Trust building + Conversion | C31: Consideration → Decision | D31: LP webinar, email sequence, Zoom setup | E31: Monitor registrations, reminder blast | F31: Post-webinar analysis, follow-up sequence | G31: Meta + Google + GHL
A32: Remarketing | B32: Re-engage warm/hot leads across platforms | C32: Decision → Conversion | D32: Dynamic creative, countdown, offers | E32: Check frequency, exclude converted | F32: Audience refresh, creative rotation | G32: All platforms + Birch
A33: Local SEO/GMB | B33: Local presence + Map visibility + Reviews | C33: Awareness (local) | D33: Ảnh, posts, review management | E33: Reply reviews, check listing accuracy | F33: Post 1 bài/tuần, update photos | G33: Google Business + Manual

Sheet 3. Master Table
A1: PHÂN BỔ – BỎ PHÚ NHUẬN – 11 DÒNG CƠ SỞ (Cần Giuộc→Tây Ninh, Rạch Giá→An Giang)
A2: Cấp | B2: Địa điểm | C2: Địa chỉ / Tỉnh | D2: HS | E2: CAC | F2: Điểm | G2: % | H2: Tổng NS | I2: Paid | J2: Tour | K2: Meta | L2: G.Search | M2: G.Display | N2: TikTok | O2: Zalo | P2: Webinar | Q2: Remarket | R2: Local SEO
A3: MN | B3: MN VA Gò Vấp | C3: 573 Lê Đức Thọ, Gò Vấp, TP.HCM | D3: 200 | E3: 0.85 | F3: =D3*E3 -> 170 | G3: =F3/F$14 -> 0.12564671 | H3: =G3*'1. Input'!B4 -> 1.6334072e+09 | I3: =G3*'1. Input'!B15 -> 1.067997e+09 | J3: =G3*'1. Input'!B10 -> 1.0051737e+08 | K3: =I3*'2. Paid Media'!B3 -> 4.0583888e+08 | L3: =I3*'2. Paid Media'!B4 -> 1.9223947e+08 | M3: =I3*'2. Paid Media'!B5 -> 74759793 | N3: =I3*'2. Paid Media'!B6 -> 1.067997e+08 | O3: =I3*'2. Paid Media'!B7 -> 74759793 | P3: =I3*'2. Paid Media'!B8 -> 53399852 | Q3: =I3*'2. Paid Media'!B9 -> 1.2815965e+08 | R3: =I3*'2. Paid Media'!B10 -> 53399852
A4: MN | B4: MN Nhân Lễ | C4: 22 D2, KDC Cần Giuộc, Tây Ninh | D4: 60 | E4: 0.85 | F4: =D4*E4 -> 51 | G4: =F4/F$14 -> 0.037694013 | H4: =G4*'1. Input'!B4 -> 4.9002217e+08 | I4: =G4*'1. Input'!B15 -> 3.2039911e+08 | J4: =G4*'1. Input'!B10 -> 30155211 | K4: =I4*'2. Paid Media'!B3 -> 1.2175166e+08 | L4: =I4*'2. Paid Media'!B4 -> 57671840 | M4: =I4*'2. Paid Media'!B5 -> 22427938 | N4: =I4*'2. Paid Media'!B6 -> 32039911 | O4: =I4*'2. Paid Media'!B7 -> 22427938 | P4: =I4*'2. Paid Media'!B8 -> 16019956 | Q4: =I4*'2. Paid Media'!B9 -> 38447894 | R4: =I4*'2. Paid Media'!B10 -> 16019956
A5: MN | B5: MN Thái Sơn | C5: KDC Thái Sơn, Cần Giuộc, Tây Ninh | D5: 60 | E5: 0.85 | F5: =D5*E5 -> 51 | G5: =F5/F$14 -> 0.037694013 | H5: =G5*'1. Input'!B4 -> 4.9002217e+08 | I5: =G5*'1. Input'!B15 -> 3.2039911e+08 | J5: =G5*'1. Input'!B10 -> 30155211 | K5: =I5*'2. Paid Media'!B3 -> 1.2175166e+08 | L5: =I5*'2. Paid Media'!B4 -> 57671840 | M5: =I5*'2. Paid Media'!B5 -> 22427938 | N5: =I5*'2. Paid Media'!B6 -> 32039911 | O5: =I5*'2. Paid Media'!B7 -> 22427938 | P5: =I5*'2. Paid Media'!B8 -> 16019956 | Q5: =I5*'2. Paid Media'!B9 -> 38447894 | R5: =I5*'2. Paid Media'!B10 -> 16019956
A6: MN | B6: MN Mekong Xanh | C6: Lô E7, KĐT Tây Bắc, Rạch Giá, An Giang | D6: 60 | E6: 0.85 | F6: =D6*E6 -> 51 | G6: =F6/F$14 -> 0.037694013 | H6: =G6*'1. Input'!B4 -> 4.9002217e+08 | I6: =G6*'1. Input'!B15 -> 3.2039911e+08 | J6: =G6*'1. Input'!B10 -> 30155211 | K6: =I6*'2. Paid Media'!B3 -> 1.2175166e+08 | L6: =I6*'2. Paid Media'!B4 -> 57671840 | M6: =I6*'2. Paid Media'!B5 -> 22427938 | N6: =I6*'2. Paid Media'!B6 -> 32039911 | O6: =I6*'2. Paid Media'!B7 -> 22427938 | P6: =I6*'2. Paid Media'!B8 -> 16019956 | Q6: =I6*'2. Paid Media'!B9 -> 38447894 | R6: =I6*'2. Paid Media'!B10 -> 16019956
A7: TH | B7: TH VA Gò Vấp | C7: 160/72 Phan Huy Ích, Gò Vấp, TP.HCM | D7: 150 | E7: 1 | F7: =D7*E7 -> 150 | G7: =F7/F$14 -> 0.11086475 | H7: =G7*'1. Input'!B4 -> 1.4412417e+09 | I7: =G7*'1. Input'!B15 -> 9.4235033e+08 | J7: =G7*'1. Input'!B10 -> 88691796 | K7: =I7*'2. Paid Media'!B3 -> 3.5809313e+08 | L7: =I7*'2. Paid Media'!B4 -> 1.6962306e+08 | M7: =I7*'2. Paid Media'!B5 -> 65964523 | N7: =I7*'2. Paid Media'!B6 -> 94235033 | O7: =I7*'2. Paid Media'!B7 -> 65964523 | P7: =I7*'2. Paid Media'!B8 -> 47117517 | Q7: =I7*'2. Paid Media'!B9 -> 1.1308204e+08 | R7: =I7*'2. Paid Media'!B10 -> 47117517
A8: TH | B8: TH VA Bình Tân | C8: Số 7 đường 38A, Tân Tạo, Bình Tân, TP.HCM | D8: 150 | E8: 1 | F8: =D8*E8 -> 150 | G8: =F8/F$14 -> 0.11086475 | H8: =G8*'1. Input'!B4 -> 1.4412417e+09 | I8: =G8*'1. Input'!B15 -> 9.4235033e+08 | J8: =G8*'1. Input'!B10 -> 88691796 | K8: =I8*'2. Paid Media'!B3 -> 3.5809313e+08 | L8: =I8*'2. Paid Media'!B4 -> 1.6962306e+08 | M8: =I8*'2. Paid Media'!B5 -> 65964523 | N8: =I8*'2. Paid Media'!B6 -> 94235033 | O8: =I8*'2. Paid Media'!B7 -> 65964523 | P8: =I8*'2. Paid Media'!B8 -> 47117517 | Q8: =I8*'2. Paid Media'!B9 -> 1.1308204e+08 | R8: =I8*'2. Paid Media'!B10 -> 47117517
A9: TH | B9: TH Thái Sơn | C9: KDC Thái Sơn, Cần Giuộc, Tây Ninh | D9: 60 | E9: 1 | F9: =D9*E9 -> 60 | G9: =F9/F$14 -> 0.044345898 | H9: =G9*'1. Input'!B4 -> 5.7649667e+08 | I9: =G9*'1. Input'!B15 -> 3.7694013e+08 | J9: =G9*'1. Input'!B10 -> 35476718 | K9: =I9*'2. Paid Media'!B3 -> 1.4323725e+08 | L9: =I9*'2. Paid Media'!B4 -> 67849224 | M9: =I9*'2. Paid Media'!B5 -> 26385809 | N9: =I9*'2. Paid Media'!B6 -> 37694013 | O9: =I9*'2. Paid Media'!B7 -> 26385809 | P9: =I9*'2. Paid Media'!B8 -> 18847007 | Q9: =I9*'2. Paid Media'!B9 -> 45232816 | R9: =I9*'2. Paid Media'!B10 -> 18847007
A10: TH | B10: TH Mekong Xanh | C10: Lô E7, KĐT Tây Bắc, Rạch Giá, An Giang | D10: 60 | E10: 1 | F10: =D10*E10 -> 60 | G10: =F10/F$14 -> 0.044345898 | H10: =G10*'1. Input'!B4 -> 5.7649667e+08 | I10: =G10*'1. Input'!B15 -> 3.7694013e+08 | J10: =G10*'1. Input'!B10 -> 35476718 | K10: =I10*'2. Paid Media'!B3 -> 1.4323725e+08 | L10: =I10*'2. Paid Media'!B4 -> 67849224 | M10: =I10*'2. Paid Media'!B5 -> 26385809 | N10: =I10*'2. Paid Media'!B6 -> 37694013 | O10: =I10*'2. Paid Media'!B7 -> 26385809 | P10: =I10*'2. Paid Media'!B8 -> 18847007 | Q10: =I10*'2. Paid Media'!B9 -> 45232816 | R10: =I10*'2. Paid Media'!B10 -> 18847007
A11: THCS | B11: THCS VA Gò Vấp | C11: 160/72 Phan Huy Ích, Gò Vấp, TP.HCM | D11: 200 | E11: 1.2 | F11: =D11*E11 -> 240 | G11: =F11/F$14 -> 0.17738359 | H11: =G11*'1. Input'!B4 -> 2.3059867e+09 | I11: =G11*'1. Input'!B15 -> 1.5077605e+09 | J11: =G11*'1. Input'!B10 -> 1.4190687e+08 | K11: =I11*'2. Paid Media'!B3 -> 5.72949e+08 | L11: =I11*'2. Paid Media'!B4 -> 2.713969e+08 | M11: =I11*'2. Paid Media'!B5 -> 1.0554324e+08 | N11: =I11*'2. Paid Media'!B6 -> 1.5077605e+08 | O11: =I11*'2. Paid Media'!B7 -> 1.0554324e+08 | P11: =I11*'2. Paid Media'!B8 -> 75388027 | Q11: =I11*'2. Paid Media'!B9 -> 1.8093126e+08 | R11: =I11*'2. Paid Media'!B10 -> 75388027
A12: THPT | B12: THPT VA Gò Vấp | C12: 160/72 Phan Huy Ích, Gò Vấp, TP.HCM | D12: 200 | E12: 1.35 | F12: =D12*E12 -> 270 | G12: =F12/F$14 -> 0.19955654 | H12: =G12*'1. Input'!B4 -> 2.594235e+09 | I12: =G12*'1. Input'!B15 -> 1.6962306e+09 | J12: =G12*'1. Input'!B10 -> 1.5964523e+08 | K12: =I12*'2. Paid Media'!B3 -> 6.4456763e+08 | L12: =I12*'2. Paid Media'!B4 -> 3.0532151e+08 | M12: =I12*'2. Paid Media'!B5 -> 1.1873614e+08 | N12: =I12*'2. Paid Media'!B6 -> 1.6962306e+08 | O12: =I12*'2. Paid Media'!B7 -> 1.1873614e+08 | P12: =I12*'2. Paid Media'!B8 -> 84811530 | Q12: =I12*'2. Paid Media'!B9 -> 2.0354767e+08 | R12: =I12*'2. Paid Media'!B10 -> 84811530
A13: Liên cấp | B13: Brand hệ thống | C13: Retarget + brand awareness chung | D13: 100 | E13: 1 | F13: =D13*E13 -> 100 | G13: =F13/F$14 -> 0.07390983 | H13: =G13*'1. Input'!B4 -> 9.6082779e+08 | I13: =G13*'1. Input'!B15 -> 6.2823356e+08 | J13: =G13*'1. Input'!B10 -> 59127864 | K13: =I13*'2. Paid Media'!B3 -> 2.3872875e+08 | L13: =I13*'2. Paid Media'!B4 -> 1.1308204e+08 | M13: =I13*'2. Paid Media'!B5 -> 43976349 | N13: =I13*'2. Paid Media'!B6 -> 62823356 | O13: =I13*'2. Paid Media'!B7 -> 43976349 | P13: =I13*'2. Paid Media'!B8 -> 31411678 | Q13: =I13*'2. Paid Media'!B9 -> 75388027 | R13: =I13*'2. Paid Media'!B10 -> 31411678
A14: TỔNG | D14: =SUM(D3:D13) -> 1300 | F14: =SUM(F3:F13) -> 1353 | G14: =SUM(G3:G13) -> 1 | H14: =SUM(H3:H13) -> 13000000000 | I14: =SUM(I3:I13) -> 8500000000 | J14: =SUM(J3:J13) -> 800000000 | K14: =SUM(K3:K13) -> 3230000000 | L14: =SUM(L3:L13) -> 1530000000 | M14: =SUM(M3:M13) -> 595000000 | ... R14: =SUM(R3:R13) -> 425000000

Sheet 4. Funnel
A1: PHỄU TUYỂN SINH 2026 — CHI TIẾT TỪNG CHIẾN DỊCH, ĐỊA ĐIỂM, CHƯƠNG TRÌNH
A3: A. KIẾN TRÚC TỔNG THỂ — 24 PHỄU TUYỂN SINH
A4: Mỗi phễu gồm 4-6 trang (pages), mỗi trang có URL riêng, tracking riêng, và remarketing audience riêng.
A5: Tất cả landing pages được xây trên GoHighLevel (GHL), domain: forms.truongvietanh.com
A7: STT | B7: Tên Phễu (Funnel Name) | C7: Mã phễu | D7: Cấp học | E7: Cơ sở | F7: Số trang | G7: URL gốc | H7: Mục tiêu | I7: Traffic sources | J7: Target leads/tháng | K7: Remarketing audience | L7: Trạng thái
A8: 1 | B8: Tuyển Sinh Mầm Non — Tổng | C8: FNL-MN-MAIN | D8: Mầm non | E8: Tất cả | F8: 6 | G8: forms.truongvietanh.com/tuyen-sinh-mam-non | H8: Lead → Tour → Enroll | I8: Meta Ads, Zalo Ads, Google | J8: 80 | K8: mn_visitors, mn_form_start, mn_form_complete | L8: ⬜ Cần tạo
A9: 2 | B9: Tuyển Sinh Tiểu Học — Tổng | C9: FNL-TH-MAIN | D9: Tiểu học | E9: Tất cả | F9: 6 | G9: forms.truongvietanh.com/tuyen-sinh-tieu-hoc | H9: Lead → Tour → Enroll | I9: Meta Ads, Google, Zalo | J9: 60 | K9: th_visitors, th_form_start, th_form_complete | L9: ⬜ Cần tạo
A10: 3 | B10: Tuyển Sinh THCS — Tổng | C10: FNL-THCS-MAIN | D10: THCS | E10: VA Gò Vấp | F10: 6 | G10: forms.truongvietanh.com/tuyen-sinh-thcs | H10: Lead → Tour → Enroll | I10: Meta Ads, Google, TikTok | J10: 40 | K10: thcs_visitors, thcs_form_start | L10: ⬜ Cần tạo
A11: 4 | B11: Tuyển Sinh THPT — Tổng | C11: FNL-THPT-MAIN | D11: THPT | E11: VA Gò Vấp | F11: 6 | G11: forms.truongvietanh.com/tuyen-sinh-thpt | H11: Lead → Tour → Enroll | I11: Meta Ads, Google, TikTok | J11: 30 | K11: thpt_visitors, thpt_form_start | L11: ⬜ Cần tạo
A12: 5 | B12: MN VA Gò Vấp — Campus Funnel | C12: FNL-MN-GV | D12: Mầm non | E12: MN VA Gò Vấp | F12: 5 | G12: forms.truongvietanh.com/mn-go-vap | H12: Lead → Tour cơ sở | I12: Meta (geo GV), Zalo | J12: 20 | K12: mn_gv_visitors | L12: ⬜ Cần tạo
A13: 6 | B13: MN Nhân Lễ — Campus Funnel | C13: FNL-MN-NL | D13: Mầm non | E13: MN Nhân Lễ | F13: 5 | G13: forms.truongvietanh.com/mn-nhan-le | H13: Lead → Tour cơ sở | I13: Meta (geo NL), Zalo | J13: 15 | K13: mn_nl_visitors | L13: ⬜ Cần tạo
A14: 7 | B14: MN+TH Thái Sơn — Campus Funnel | C14: FNL-TS | D14: MN+TH | E14: Thái Sơn | F14: 5 | G14: forms.truongvietanh.com/thai-son | H14: Lead → Tour cơ sở | I14: Meta (geo TS), Zalo | J14: 15 | K14: ts_visitors | L14: ⬜ Cần tạo
A15: 8 | B15: MN+TH Mekong Xanh — Campus Funnel | C15: FNL-MK | D15: MN+TH | E15: Mekong Xanh | F15: 5 | G15: forms.truongvietanh.com/mekong-xanh | H15: Lead → Tour cơ sở | I15: Meta (geo MK), Zalo | J15: 15 | K15: mk_visitors | L15: ⬜ Cần tạo
A16: 9 | B16: TH VA Gò Vấp — Campus Funnel | C16: FNL-TH-GV | D16: Tiểu học | E16: TH VA Gò Vấp | F16: 5 | G16: forms.truongvietanh.com/th-go-vap | H16: Lead → Tour cơ sở | I16: Meta (geo GV), Google | J16: 20 | K16: th_gv_visitors | L16: ⬜ Cần tạo
A17: 10 | B17: TH VA Bình Tân — Campus Funnel | C17: FNL-TH-BT | D17: Tiểu học | E17: TH VA Bình Tân | F17: 5 | G17: forms.truongvietanh.com/th-binh-tan | H17: Lead → Tour cơ sở | I17: Meta (geo BT), Zalo | J17: 15 | K17: th_bt_visitors | L17: ⬜ Cần tạo
A18: 11 | B18: Open Day T4 — Event Funnel | C18: FNL-OD-T4 | D18: Tất cả | E18: GV + GV | F18: 4 | G18: forms.truongvietanh.com/open-day-thang-4 | H18: Register → Attend | I18: All channels | J18: 100 đăng ký | K18: od_t4_visitors, od_t4_registered | L18: ⬜ Cần tạo
... A31: 24 | B31: Khai Giảng 2026 — Welcome | C31: FNL-KG | D31: Tất cả | E31: Tất cả | F31: 3 | G31: forms.truongvietanh.com/khai-giang-2026 | H31: Info → Confirm → Welcome | I31: Email, Zalo, SMS | J31: All enrolled | K31: kg_visitors | L31: ⬜ Cần tạo
A34: B. CHI TIẾT TỪNG TRANG — PHỄU "TUYỂN SINH MẦM NON" (FNL-MN-MAIN)
A35: Đây là mẫu chi tiết cho 1 phễu. Các phễu khác có cấu trúc tương tự, customize theo cấp học/cơ sở.
A37: Trang | B37: URL đầy đủ | C37: Tên trang (Page Title) | D37: Mục đích | E37: Nội dung chính trên trang | F37: Form fields | G37: CTA Button | H37: Pixel Events fired | I37: Remarketing Audience tạo | J37: Next step nếu submit | K37: Next step nếu KHÔNG submit | L37: A/B Test variants | M37: Ghi chú
A38: Trang 1: Landing Page chính | B38: https://forms.truongvietanh.com/tuyen-sinh-mam-non | C38: Tuyển Sinh Mầm Non 2026 — Trường Việt Anh | Nơi Con Yêu Lớn Khôn | D38: Thu hút → Giữ chân → Điền form | E38: Hero banner (hình HS mầm non vui vẻ) + Headline "Cho Con Khởi Đầu Tốt Nhất" → 3 USP icons (An toàn, Chương trình quốc tế, Giáo viên tận tâm) → Video tour trường 60s (autoplay muted) → 6 cơ sở trên bản đồ (click → campus page) → Chương trình học: Montessori, STEM, Song ngữ → 3 Testimonials PH (video + quote) → FAQ accordion (5 câu hỏi phổ biến) → CTA form cuối trang | F38: Họ tên PH*, SĐT*, Email, Tên bé, Năm sinh bé, Cơ sở quan tâm (dropdown 6), Nguồn biết (hidden UTM) | G38: ĐĂNG KÝ TƯ VẤN MIỄN PHÍ → | H38: PageView, ViewContent, InitiateCheckout (scroll 70%), Lead (form submit) | I38: mn_page_visitors (PageView) mn_page_engaged (ViewContent, >30s) mn_form_started (InitiateCheckout) mn_form_complete (Lead) | J38: → Trang 2: Thank You + Booking Tour | K38: → Retarget sau 1 ngày: Ad "Bạn đã xem chương trình MN — Đặt lịch tham quan ngay" → KHÔNG quay lại trang 1, đưa sang Trang 3 (Testimonial) | L38: Variant A: Hero = Video Variant B: Hero = Carousel hình Test 2 tuần, 50/50 traffic | M38: Mobile-first, load <3s, Lazy load images
A39: Trang 2: Thank You + Book Tour | B39: https://forms.truongvietanh.com/tuyen-sinh-mam-non/cam-on | C39: Cảm Ơn Bạn! Đặt Lịch Tham Quan Trường Ngay | D39: Confirm lead + Book tour ngay | E39: Heading: "Cảm ơn [Tên PH]! Chúng tôi sẽ liên hệ trong 30 phút" → GHL Calendar embed: chọn cơ sở → chọn ngày/giờ tour → Checklist "Khi đến tham quan, bạn sẽ được:" → Video "Một buổi tham quan tại Việt Anh" 2 phút → Social proof: "200+ PH đã đăng ký tham quan tháng này" → Share buttons: FB, Zalo | F39: Cơ sở (pre-filled), Ngày tour, Giờ tour, Số người đi cùng | G39: ĐẶT LỊCH THAM QUAN → | H39: Purchase (=Tour booked), Schedule | I39: mn_tour_booked (Purchase) | J39: → Trang 2b: Tour Confirmation + Add to Calendar | K39: → Nếu không book: GHL workflow Day+1 Email nhắc, Day+3 SMS, Day+5 Zalo | L39: Variant A: Calendar trước Variant B: Video trước rồi Calendar | M39: Pre-fill tên PH từ form trước
A40: Trang 2b: Tour Confirmation | B40: https://forms.truongvietanh.com/tuyen-sinh-mam-non/xac-nhan-tour | C40: Xác Nhận Lịch Tham Quan — [Cơ sở] — [Ngày/Giờ] | D40: Confirm + prepare PH cho tour | E40: Heading: "Tuyệt vời! Hẹn gặp bạn tại [Cơ sở] vào [Ngày/Giờ]" → Bản đồ Google Maps cơ sở → Hướng dẫn đường đi + chỗ đậu xe → Checklist chuẩn bị: mang theo CMND, bé đi cùng → Add to Google Calendar / iCal buttons → Zalo OA QR code: "Follow để nhận nhắc nhở" | F40: Không có form (confirmation only) | G40: THÊM VÀO LỊCH → | H40: CompleteRegistration | I40: mn_tour_confirmed | J40: → GHL: -24h SMS reminder, -2h Zalo reminder | K40: → Nếu no-show: Day+1 email "Rất tiếc bạn không đến — Đặt lại lịch?" | L40: N/A | M40: Auto-generate từ GHL calendar data
A41: Trang 3: Testimonial Social Proof | B41: https://forms.truongvietanh.com/tuyen-sinh-mam-non/phu-huynh-noi-gi | C41: Phụ Huynh Nói Gì Về Trường Việt Anh? — Mầm Non | D41: Build trust cho leads đã visit trang 1 nhưng chưa submit form | E41: Heading: "Hơn 5,000 Phụ Huynh Đã Tin Tưởng Chọn Việt Anh" → 10 video testimonials PH (30-60s mỗi video) → 20 quote cards với hình PH + con → Rating stars: 4.8/5 (500+ đánh giá) → Before/After stories: "Bé nhút nhát → Tự tin sau 3 tháng" → CTA form: "Bạn cũng muốn con trải nghiệm?" | F41: Họ tên PH*, SĐT*, Cấp học quan tâm | G41: ĐĂNG KÝ TRẢI NGHIỆM → | H41: ViewContent, Lead (form submit) | I41: mn_testimonial_viewers | J41: → Trang 2: Thank You + Book Tour | K41: → Retarget: Ad "Xem thêm câu chuyện PH" → Trang 4 (Chương trình) | L41: Variant A: Video testimonials trước Variant B: Quote cards trước | M41: REMARKETING PAGE — chỉ cho người đã visit Trang 1 mà chưa submit
A42: Trang 4: Chương Trình Học Chi Tiết | B42: https://forms.truongvietanh.com/tuyen-sinh-mam-non/chuong-trinh | C42: Chương Trình Mầm Non Quốc Tế — Montessori, STEM, Song Ngữ | D42: Cung cấp thông tin sâu cho PH đang so sánh trường | E42: Heading: "Chương Trình Được Thiết Kế Riêng Cho Từng Giai Đoạn Phát Triển" → Infographic: Lộ trình 3 năm MN (Nhà trẻ → Mầm → Lá) → 5 tab content: Montessori, STEM, Song ngữ, Kỹ năng sống, Thể chất → So sánh bảng: Việt Anh vs Trường công vs Trường tư khác → Download PDF: "Cẩm Nang Chọn Trường Mầm Non" (lead magnet) → CTA: "Đăng ký để nhận tư vấn chương trình phù hợp cho bé" | F42: Họ tên PH*, SĐT*, Email*, Tên bé, Tuổi bé, Chương trình quan tâm (multi-select) | G42: TẢI CẨM NANG + TƯ VẤN → | H42: ViewContent, AddToCart (download PDF), Lead (form) | I42: mn_program_viewers mn_pdf_downloaded (AddToCart) | J42: → Trang 2: Thank You + Book Tour (nếu form) → Email: Gửi PDF + Nurture sequence | K42: → Retarget: Ad "So sánh chương trình — Tham quan để cảm nhận" → Trang 5 | L42: Variant A: Tab content Variant B: Long scroll | M42: REMARKETING PAGE — cho người đã xem Trang 3 hoặc Trang 1 lần 2+
A43: Trang 5: Học Phí & Ưu Đãi | B43: https://forms.truongvietanh.com/tuyen-sinh-mam-non/hoc-phi | C43: Học Phí Mầm Non 2026 — Ưu Đãi Đặc Biệt Khi Đăng Ký Sớm | D43: Cuối funnel — quyết định tài chính, push enrollment | E43: Heading: "Đầu Tư Cho Con — Học Phí Minh Bạch, Ưu Đãi Hấp Dẫn" → Bảng học phí theo cơ sở (6 cơ sở) → Phí bao gồm: ăn, xe, đồng phục, sách, ngoại khóa → Ưu đãi: Giảm 10% nếu đăng ký trước 30/6, Giảm 5% con thứ 2 → Phương thức thanh toán: trả góp, học kỳ, năm → Học bổng: link đến FNL-HB → Countdown timer: "Ưu đãi còn [X] ngày" → CTA: "Đăng ký ngay để nhận ưu đãi" | F43: Họ tên PH*, SĐT*, Cơ sở*, Cấp học*, Phương thức TT, Mã giới thiệu (optional) | G43: ĐĂNG KÝ NHẬN ƯU ĐÃI → | H43: ViewContent, AddPaymentInfo (view học phí), Lead (form), Purchase (nếu đặt cọc online) | I43: mn_tuition_viewers mn_tuition_engaged (>60s) | J43: → Trang 2: Thank You + Book Tour → GHL: High-priority lead, auto-call trong 15 phút | K43: → Retarget: Ad "Chỉ còn [X] ngày ưu đãi — Đăng ký ngay!" (urgency) | L43: Variant A: Countdown timer Variant B: Social proof counter | M43: BOTTOM FUNNEL — người xem trang này = ý định cao, ưu tiên follow up nhanh
A46: C. REMARKETING SEQUENCES — LOGIC CHUYỂN TRANG PHỄU
A47: Nguyên tắc vàng: KHÔNG BAO GIỜ cho khách hàng xem lại trang họ đã thấy. Luôn đưa sang trang tiếp theo trong phễu.
A49: Hành vi khách hàng | B49: Audience tạo | C49: Audience loại trừ (Exclude) | D49: Ads hiển thị | E49: Landing page đích | F49: Thời gian trigger | G49: Budget/ngày | H49: Kênh chạy | I49: Duration | J49: Ghi chú
A50: Đã vào Trang 1 (LP chính) nhưng CHƯA điền form | B50: mn_page_visitors | C50: mn_form_complete (đã điền form) mn_tour_booked (đã book tour) | D50: Ad: "Hơn 5,000 PH đã tin tưởng — Xem họ nói gì" Format: Video testimonial 30s | E50: Trang 3: forms.truongvietanh.com/tuyen-sinh-mam-non/phu-huynh-noi-gi | F50: Sau 1 ngày (24h) | G50: 200,000 VND | H50: Meta Ads, TikTok | I50: 14 ngày | J50: KHÔNG đưa về Trang 1. Đưa sang Testimonial để build trust
A51: Đã vào Trang 1 LẦN 2+ (return visitor) nhưng chưa submit | B51: mn_page_visitors (frequency ≥2) | C51: mn_form_complete | D51: Ad: "Chương trình MN Quốc Tế — So sánh chi tiết" Format: Carousel 5 slides | E51: Trang 4: forms.truongvietanh.com/tuyen-sinh-mam-non/chuong-trinh | F51: Ngay lập tức | G51: 150,000 VND | H51: Meta Ads | I51: 14 ngày | J51: Return visitor = quan tâm cao. Cung cấp thông tin sâu hơn
A52: Đã xem Trang 3 (Testimonial) nhưng chưa submit form | B52: mn_testimonial_viewers | C52: mn_form_complete mn_page_visitors (Trang 4 đã xem) | D52: Ad: "So sánh chương trình — Montessori vs STEM vs Song ngữ" Format: Infographic carousel | E52: Trang 4: forms.truongvietanh.com/tuyen-sinh-mam-non/chuong-trinh | F52: Sau 2 ngày | G52: 150,000 VND | H52: Meta Ads | I52: 14 ngày | J52: Đã tin tưởng (xem testimonial) → giờ cần thông tin chương trình
A53: Đã xem Trang 4 (Chương trình) nhưng chưa submit | B53: mn_program_viewers | C53: mn_form_complete mn_tuition_viewers | D53: Ad: "Học phí MN 2026 — Ưu đãi giảm 10% đăng ký sớm" Format: Single image + countdown | E53: Trang 5: forms.truongvietanh.com/tuyen-sinh-mam-non/hoc-phi | F53: Sau 2 ngày | G53: 200,000 VND | H53: Meta Ads, Zalo | I53: 14 ngày | J53: Đã nghiên cứu chương trình → giờ quan tâm giá cả
A54: Đã xem Trang 5 (Học phí) nhưng chưa submit | B54: mn_tuition_viewers | C54: mn_form_complete | D54: Ad: "Ưu đãi chỉ còn [X] ngày — Đăng ký tư vấn ngay" Format: Video urgency 15s + CTA | E54: Trang 1: forms.truongvietanh.com/tuyen-sinh-mam-non (quay lại LP với variant B) | F54: Sau 1 ngày | G54: 300,000 VND | H54: Meta, Zalo, TikTok | I54: 7 ngày | J54: Đã xem hết funnel → urgency push. Lần này dùng Variant B của Trang 1
A55: Đã điền form Trang 1 nhưng CHƯA book tour | B55: mn_form_complete | C55: mn_tour_booked | D55: Ad: "Bạn đã đăng ký — Đặt lịch tham quan ngay hôm nay!" Format: Dynamic với tên cơ sở | E55: Trang 2: forms.truongvietanh.com/tuyen-sinh-mam-non/cam-on (scroll to calendar) | F55: Sau 2 ngày | G55: 150,000 VND | H55: Meta Ads | I55: 14 ngày | J55: Lead đã có nhưng chưa book tour. Push booking
A56: Đã book tour nhưng NO-SHOW | B56: mn_tour_booked | C56: mn_tour_confirmed (actually attended) | D56: Ad: "Rất tiếc bạn chưa đến — Đặt lại lịch tham quan" Format: Friendly reminder video | E56: Trang 2: forms.truongvietanh.com/tuyen-sinh-mam-non/cam-on | F56: Sau 1 ngày sau tour date | G56: 100,000 VND | H56: Meta, Zalo | I56: 14 ngày | J56: GHL tag "no-show" → trigger remarketing + email + Zalo message
A57: Đã tham quan (Tour completed) nhưng chưa enroll | B57: mn_tour_confirmed | C57: mn_enrolled | D57: Ad: "Bé [dynamic] đã rất thích — Đăng ký ngay để giữ chỗ" Format: Testimonial + Urgency | E57: Trang 5: forms.truongvietanh.com/tuyen-sinh-mam-non/hoc-phi | F57: Sau 3 ngày sau tour | G57: 200,000 VND | H57: Meta, Zalo, Email | I57: 30 ngày | J57: BOTTOM FUNNEL remarketing — conversion push mạnh nhất
A58: Đã download PDF cẩm nang nhưng chưa điền form tư vấn | B58: mn_pdf_downloaded | C58: mn_form_complete | D58: Ad: "Bạn đã tải Cẩm Nang — Đăng ký tư vấn để chọn chương trình phù hợp" Format: Carousel tips | E58: Trang 1: forms.truongvietanh.com/tuyen-sinh-mam-non (variant B) | F58: Sau 3 ngày | G58: 100,000 VND | H58: Meta Ads | I58: 14 ngày | J58: Lead magnet đã capture interest → push form submission
A59: Cold lead 30+ ngày không hoạt động | B59: All mn_* audiences | C59: mn_enrolled mn_active_last_14_days | D59: Ad: "Cơ hội cuối — Ưu đãi đặc biệt chỉ dành cho bạn" Format: Personalized offer | E59: Trang 5: forms.truongvietanh.com/tuyen-sinh-mam-non/hoc-phi (với param ?offer=winback) | F59: Sau 30 ngày cold | G59: 100,000 VND | H59: Meta, Zalo | I59: 14 ngày | J59: Win-back campaign. Special discount code.
A62: D. URL MAP — TẤT CẢ CÁC TRANG PHỄU THEO CƠ SỞ
...

Sheet 5. Google Ads Chi Tiết
A1: KẾ HOẠCH GOOGLE ADS – CẤU TRÚC TÀI KHOẢN + CAMPAIGN + KEYWORD + RSA + BIRCH
A3: A. CẤU TRÚC TÀI KHOẢN GOOGLE ADS
A4: Cấp độ | B4: Tên | C4: Mô tả | D4: Ngân sách | E4: Ghi chú
A5: Account | B5: VA_TuyenSinh_2026 | C5: Tài khoản chính cho tuyển sinh | D5: ='1. Input'!B15*0.25 -> 2125000000 | E5: Tổng Google = 25% Paid Media
A6: Campaign | B6: S_BRAND_System | C6: Brand search toàn hệ thống | D6: Auto | E6: Luôn bật, không pause
A7: Campaign | B7: S_MN_GV_Generic | C7: Search mầm non Gò Vấp generic | D7: Daily cap | E7: Keyword: mầm non song ngữ gò vấp
A8: Campaign | B8: S_MN_GV_HighIntent | C8: Search mầm non Gò Vấp high intent | D8: Daily cap | E8: Keyword: học phí mầm non, tuyển sinh mầm non
A9: Campaign | B9: S_MN_Tinh_Generic | C9: Search mầm non tỉnh (Tây Ninh, An Giang) | D9: Daily cap | E9: Local intent tỉnh
A10: Campaign | B10: S_TH_GV_Generic | C10: Search tiểu học Gò Vấp | D10: Daily cap | E10: Lớp 1, song ngữ, học phí
A11: Campaign | B11: S_TH_BT_Generic | C11: Search tiểu học Bình Tân | D11: Daily cap | E11: Local + song ngữ
A12: Campaign | B12: S_TH_Tinh_Generic | C12: Search tiểu học tỉnh | D12: Daily cap | E12: Thái Sơn + Mekong Xanh
A13: Campaign | B13: S_THCS_GV_Generic | C13: Search THCS Gò Vấp generic | D13: Daily cap | E13: Lớp 6, trường cấp 2
A14: Campaign | B14: S_THCS_GV_HighIntent | C14: Search THCS Gò Vấp high intent | D14: Daily cap | E14: Tuyển sinh lớp 6, học phí
A15: Campaign | B15: S_THPT_GV_Generic | C15: Search THPT Gò Vấp generic | D15: Daily cap | E15: Lớp 10, trường cấp 3
A16: Campaign | B16: S_THPT_GV_HighIntent | C16: Search THPT Gò Vấp high intent | D16: Daily cap | E16: Tuyển sinh lớp 10, học bổng
A17: Campaign | B17: S_THPT_GV_Webinar | C17: Search THPT webinar | D17: Daily cap | E17: Hội thảo, lộ trình, chọn trường
... A24: Campaign | B24: PMAX_Test | C24: Performance Max test | D24: Daily cap 2% | E24: Chỉ test từ T6, không scale sớm
A26: B. KEYWORD BANK (EXACT + PHRASE)
A27: Cấp | B27: Nhóm | C27: Match | D27: Keyword | E27: Campaign | F27: Ghi chú
A28: MN | B28: Brand | C28: Exact | D28: [trường mầm non việt anh gò vấp] | E28: S_BRAND
A29: MN | B29: Brand | C29: Exact | D29: [mầm non việt anh lê đức thọ] | E29: S_BRAND
A30: MN | B30: Generic | C30: Exact | D30: [trường mầm non song ngữ gò vấp] | E30: S_MN_GV_Generic | F30: Top KW
A31: MN | B31: Generic | C31: Exact | D31: [trường mầm non tư thục gò vấp] | E31: S_MN_GV_Generic
A32: MN | B32: Generic | C32: Phrase | D32: "trường mầm non gần nhà" | E32: S_MN_GV_Generic | F32: Local
A33: MN | B33: Generic | C33: Phrase | D33: "mầm non song ngữ" | E33: S_MN_GV_Generic
A34: MN | B34: HighIntent | C34: Exact | D34: [học phí mầm non song ngữ gò vấp] | E34: S_MN_GV_HighIntent | F34: HOT
A35: MN | B35: HighIntent | C35: Exact | D35: [tuyển sinh mầm non gò vấp] | E35: S_MN_GV_HighIntent | F35: HOT
A36: MN | B36: Pain | C36: Phrase | D36: "trường mầm non an toàn" | E36: S_MN_GV_Generic
A37: MN | B37: Pain | C37: Phrase | D37: "trường mầm non có camera" | E37: S_MN_GV_Generic
A38: TH | B38: Brand | C38: Exact | D38: [trường việt anh gò vấp] | E38: S_BRAND
A39: TH | B39: Brand | C39: Exact | D39: [trường việt anh bình tân] | E39: S_BRAND
A40: TH | B40: Generic | C40: Exact | D40: [trường tiểu học song ngữ gò vấp] | E40: S_TH_GV_Generic
A41: TH | B41: Generic | C41: Exact | D41: [trường tiểu học tư thục bình tân] | E41: S_TH_BT_Generic
A42: TH | B42: HighIntent | C42: Exact | D42: [tuyển sinh lớp 1 trường tư] | E42: S_TH_GV_HighIntent | F42: HOT
A43: TH | B43: HighIntent | C43: Exact | D43: [học phí tiểu học song ngữ] | E43: S_TH_GV_HighIntent | F43: HOT
A44: THCS | B44: Generic | C44: Exact | D44: [trường thcs tư thục gò vấp] | E44: S_THCS_GV_Generic
A45: THCS | B45: Generic | C45: Phrase | D45: "trường cấp 2 song ngữ" | E45: S_THCS_GV_Generic
A46: THCS | B46: HighIntent | C46: Exact | D46: [tuyển sinh lớp 6 trường tư] | E46: S_THCS_GV_HighIntent | F46: HOT
A47: THCS | B47: HighIntent | C47: Exact | D47: [học phí thcs song ngữ] | E47: S_THCS_GV_HighIntent
A48: THPT | B48: Generic | C48: Exact | D48: [trường thpt tư thục gò vấp] | E48: S_THPT_GV_Generic
...

Sheet 6. Meta Ads Chi Tiết
A1: KẾ HOẠCH META ADS – CẤU TRÚC + AUDIENCE + CREATIVE + PIXEL + GHL
A3: A. CẤU TRÚC TÀI KHOẢN META ADS (BỎ PHÚ NHUẬN)
A4: Campaign | B4: Objective | C4: Audience | D4: Creative | E4: Budget/tháng | F4: LP | G4: GHL Pipeline | H4: GTM/Pixel Events
A5: MN_GV_LeadGen | B5: Lead Generation | C5: Geo 5km MN GV | Age 25-40 | Interest Parenting | Lookalike 1-3% | D5: Video testi PH 15-30s + Carousel campus + Lead form | E5: =0.38*'1. Input'!B15*0.25/6 -> 1.3458333e+08 | F5: LP_MN_GV | G5: Pipeline MN | H5: Lead, ViewContent, CompleteRegistration
A6: MN_Tinh_LeadGen | B6: Lead Generation | C6: Geo Cần Giuộc (Tây Ninh) + Rạch Giá (An Giang) | Age 25-40 | D6: Video testi + Ảnh campus local + Lead form | E6: =0.38*'1. Input'!B15*0.12/6 -> 64600000 | F6: LP_MN_Tinh | G6: Pipeline MN | H6: Lead, ViewContent
A7: TH_GV_LeadGen | B7: Lead Generation | C7: Geo 8km TH GV | Age 28-45 | Lookalike PH TH | D7: Video lớp học + Carousel chương trình + Messenger | E7: =0.38*'1. Input'!B15*0.18/6 -> 96900000 | F7: LP_TH_GV | G7: Pipeline TH | H7: Lead, ViewContent
A8: TH_BT_LeadGen | B8: Lead Generation | C8: Geo 8km Bình Tân | Age 28-45 | D8: Video + Lead form | E8: =0.38*'1. Input'!B15*0.15/6 -> 80750000 | F8: LP_TH_BT | G8: Pipeline TH | H8: Lead
A9: TH_Tinh_LeadGen | B9: Lead Generation | C9: Geo Thái Sơn + Mekong Xanh | D9: Video local + Lead form | E9: =0.38*'1. Input'!B15*0.08/6 -> 43066667 | F9: LP_TH_Tinh | G9: Pipeline TH | H9: Lead
A10: THCS_GV_Conv | B10: Conversions | C10: Geo TP.HCM | Age 30-50 | Custom: Web 30d | D10: Video HS+GV + Testi 60s + Webinar ads | E10: =0.38*'1. Input'!B15*0.2/6 -> 1.0766667e+08 | F10: LP_THCS_GV | G10: Pipeline THCS | H10: Lead, WebinarReg, ViewContent
A11: THPT_GV_Conv | B11: Conversions | C11: Geo TP.HCM + miền Nam | Age 35-55 | Lookalike PH THPT | D11: Video đầu ra + Học bổng + Testi | E11: =0.38*'1. Input'!B15*0.2/6 -> 1.0766667e+08 | F11: LP_THPT_GV | G11: Pipeline THPT | H11: Lead, ScholarshipClick
A12: Remarketing_All | B12: Conversions | C12: PageView 7-30d | Exclude enrolled | Dynamic by cấp | D12: Carousel campus + ưu đãi + Countdown | E12: =0.12*'1. Input'!B15*0.5/6 -> 85000000 | F12: Dynamic | G12: Retarget tag | H12: Purchase, Lead
A14: B. PIXEL + CAPI + GTM SETUP
A15: Bước | B15: Hành động | C15: Chi tiết | D15: Tool | E15: Timeline | F15: Trạng thái
A16: 1 | B16: Cài Meta Pixel qua GTM | C16: Tạo tag Meta Pixel Base Code trong GTM → fire on All Pages | D16: GTM + Meta | E16: Ngày 1 | F16: ☐
A17: 2 | B17: Tạo Custom Events trong GTM | C17: form_submit, click_call, click_zalo, webinar_register, scholarship_click | D17: GTM | E17: Ngày 1 | F17: ☐
A18: 3 | B18: Cài Conversion API (CAPI) | C18: Server-side tracking qua GHL webhook → Meta CAPI endpoint | D18: GHL + Meta | E18: Ngày 2 | F18: ☐
A19: 4 | B19: Tạo Custom Conversions | C19: 4 events: Form MN, Form TH, Form THCS/THPT, Tour Scheduled | D19: Meta Events Manager | E19: Ngày 2 | F19: ☐
A20: 5 | B20: Verify domain | C20: Xác minh domain truongvietanh.com trong Business Manager | D20: Meta Business Suite | E20: Ngày 1 | F20: ☐
A21: 6 | B21: Tạo Audience Library | C21: 8 saved audiences (4 cấp × 2 geo) + Lookalike 1%/3%/5% + Custom 7d/14d/30d/60d | D21: Meta Ads Manager | E21: Ngày 2 | F21: ☐
A22: 7 | B22: Sync GHL → Meta | C22: Upload enrolled parents list → Exclusion | Monthly refresh | D22: GHL + Meta | E22: Tuần 2 | F22: ☐
A23: 8 | B23: Setup Birch cho Meta | C23: Kết nối Meta Ads → Birch | Tạo rules CPL, budget pacing | D23: Birch | E23: Ngày 3 | F23: ☐
A25: C. CREATIVE RESOURCE PLAN – PHÂN BỔ ẢNH/VIDEO CHO META ADS
A26: Campaign | B26: Loại Creative | C26: Số lượng | D26: Format | E26: Nội dung | F26: Nguồn ảnh/video | G26: Refresh cycle | H26: A/B Test | I26: Ghi chú
A27: MN_GV_LeadGen | B27: Video testimonial PH | C27: 3 | D27: 9:16 Reel 15-30s | E27: PH chia sẻ: "Con tôi vui khi đến trường" | F27: Quay tại campus, PH thật | G27: 3 tuần | H27: Test 3 PH khác nhau | I27: Hook 3s quan trọng nhất
A28: MN_GV_LeadGen | B28: Carousel campus | C28: 2 | D28: 1:1 1080x1080 | E28: 6 slides: Sân chơi, Phòng học, Bếp ăn, Camera, GV, Hoạt động | F28: Chụp tại campus GV | G28: 4 tuần | H28: Test order slides | I28: Ảnh thật, không stock
A29: MN_GV_LeadGen | B29: Lead Form ad | C29: 2 | D29: 1:1 1080x1080 | E29: Image + text: "Đăng ký tour MN Việt Anh" | Form prefill | F29: Thiết kế Canva | G29: 2 tuần | H29: Test benefit vs offer | I29: Form ngắn: Tên+SĐT+Cấp
A30: TH_GV_LeadGen | B30: Video "Nền tảng lớp 1" | C30: 2 | D30: 9:16 Reel 30-60s | E30: Lớp học thực tế, HS đọc TA, GV tương tác | F30: Quay tại TH GV | G30: 4 tuần | H30: Test 30s vs 60s | I30: Show HS thật đang học
A31: TH_GV_LeadGen | B31: Carousel chương trình | C31: 2 | D31: 1:1 1080x1080 | E31: 6 slides: Chương trình, TA, STEM, Ngoại khóa, Sĩ số, Tour | F31: Chụp + thiết kế | G31: 4 tuần | H31: Test headline | I31: Infographic style
A32: TH_BT_LeadGen | B32: Image + text local | C32: 3 | D32: 1:1 1080x1080 | E32: Ảnh campus BT + text "Trường tư song ngữ Bình Tân" | F32: Chụp tại campus BT | G32: 3 tuần | H32: Test 3 images | I32: Local feel quan trọng
A33: THCS_GV_LeadGen | B33: Video testi HS + GV | C33: 3 | D33: 9:16 Reel 30-60s | E33: HS THCS chia sẻ + GV chủ nhiệm nói về lộ trình | F33: Quay tại THCS GV | G33: 3 tuần | H33: Test HS vs GV focus | I33: Emotional storytelling
A34: THCS_GV_Webinar | B34: Video invite webinar | C34: 2 | D34: 9:16 Reel 15s | E34: Teaser: "Hội thảo chuyển cấp 5→6 – Miễn phí" | F34: Thiết kế motion | G34: 2 tuần | H34: Test countdown vs benefit | I34: Urgency + value
A35: THPT_GV_LeadGen | B35: Video "Lộ trình THPT" | C35: 3 | D35: 9:16 Reel 30-60s | E35: Alumni ĐH chia sẻ + BGH nói về đầu ra | F35: Quay tại THPT + ĐH | G35: 3 tuần | H35: Test alumni vs BGH | I35: Data-driven: % ĐH top
A36: THPT_HocBong | B36: Image học bổng | C36: 3 | D36: 1:1 1080x1080 | E36: "Học bổng lên đến 100% – Deadline [ngày]" | Bold design | F36: Thiết kế Canva/AI | G36: 2 tuần | H36: Test % vs giá trị tiền | I36: Deadline rõ ràng
A37: Retarget_7d_Hot | B37: Dynamic creative | C37: 4 | D37: 1:1 multi-format | E37: Testimonial + ưu đãi + countdown + campus | F37: Mix từ kho | G37: 2 tuần | H37: Auto by Meta | I37: DCO cho remarketing
A38: Brand_Awareness | B38: Brand video 15s | C38: 2 | D38: 16:9 + 9:16 | E38: Montage: 8 campus, HS vui, USP overlay, logo end | F38: Quay + edit pro | G38: 6 tuần | H38: Test 15s vs 30s | I38: CPM optimize
A41: D. DAILY OPERATIONS – META ADS HÀNG NGÀY
A42: Thời gian | B42: Công việc | C42: Chi tiết | D42: Tool | E42: KPI check | F42: Action nếu lệch | G42: Ai làm
