Workbook

Sheet I. Chân Dung KH
A1: CHÂN DUNG KHÁCH HÀNG (PERSONA) – THEO SẢN PHẨM VÀ ĐỊA ĐIỂM
A2: Phân tích chi tiết đối tượng phụ huynh mục tiêu, nỗi đau, insight và messaging phù hợp cho từng cấp học và từng địa điểm
A4: A. PERSONA THEO CẤP HỌC
A5: Cấp học | B5: Tên Persona | C5: Tuổi | D5: Giới tính | E5: Nghề nghiệp | F5: Thu nhập/tháng | G5: Hành vi Online | H5: Kênh tiếp cận chính | I5: Nỗi đau #1 | J5: Nỗi đau #2 | K5: Nỗi đau #3 | L5: Insight mua hàng | M5: Messaging chính | N5: CTA hiệu quả | O5: Objection thường gặp | P5: Cách xử lý Objection
A6: MN (Mầm non) | B6: Chị Lan – Mẹ bỉm sữa | C6: 26-35 | D6: Nữ 85% | E6: Nhân viên VP, kinh doanh nhỏ | F6: 15-30 triệu | G6: Facebook 3h/ngày, Zalo, TikTok, group MN | H6: Meta Ads, Zalo OA, TikTok | I6: Sợ con bị bắt nạt / không an toàn | J6: Thiếu thời gian đưa đón, cần trường gần nhà | K6: Lo giáo viên không tận tâm, thay đổi liên tục | L6: Tin review PH khác > quảng cáo; Quyết định nhanh nếu tour ấn tượng | M6: Môi trường an toàn, camera 24/7, GV tận tâm, gần nhà | N6: Đăng ký tham quan trường MIỄN PHÍ | O6: Học phí cao hơn trường khác | P6: So sánh giá trị: ăn sạch, GV/trẻ tỷ lệ thấp, camera, ngoại khóa
A7: MN (Mầm non) | B7: Anh Tuấn – Ba trẻ quan tâm GD | C7: 30-40 | D7: Nam 15% | E7: Quản lý, kỹ sư, CNTT | F7: 25-50 triệu | G7: Google Search, YouTube review | H7: Google Ads, YouTube | I7: Muốn con phát triển toàn diện sớm | J7: Lo trường không có chương trình song ngữ tốt | K7: Không biết trường nào uy tín gần nhà | L7: So sánh kỹ trên Google trước khi tour | M7: Song ngữ từ 3 tuổi, chương trình STEAM | N7: Xem chi tiết chương trình học | O7: Muốn chờ vợ quyết định | P7: Mời cả 2 PH cùng tour, tặng ưu đãi
A8: TH (Tiểu học) | B8: Chị Mai – PH lớp 1 lo lắng | C8: 30-42 | D8: Nữ 75% | E8: Nhân viên, giáo viên, kinh doanh | F8: 20-40 triệu | G8: Facebook, Zalo group, tìm Google | H8: Meta Ads, Google Search, Zalo | I8: Sợ con không theo kịp chương trình | J8: Lo trường tư "nhẹ" hơn trường công | K8: Áp lực tiếng Anh – con chưa có nền tảng | L8: Tham khảo 3-5 trường trước khi chọn; Tour 2 lần | M8: Lộ trình tiếng Anh rõ ràng, sĩ số nhỏ 25-30, GV theo sát | N8: Đặt lịch tham quan + tư vấn 1-1 | O8: Trường công miễn phí mà cũng tốt | P8: Sĩ số 50 vs 25, không ngoại khóa, GV không theo sát
A9: TH (Tiểu học) | B9: Anh Hùng – PH chuyển con từ công sang tư | C9: 35-45 | D9: Nam 25% | E9: Chủ DN nhỏ, quản lý | F9: 30-60 triệu | G9: Google, Facebook, hỏi bạn bè | H9: Google Ads, Remarketing | I9: Con đang học công nhưng không phát triển | J9: Muốn môi trường tốt hơn, ít bạo lực | K9: Lo con không thích nghi khi chuyển | L9: Quyết định nhanh khi thấy cơ sở vật chất tốt | M9: Chuyển cấp linh hoạt, hỗ trợ hòa nhập, CSVC hiện đại | N9: Đăng ký chuyển trường – Hỗ trợ hồ sơ nhanh | O9: Con đã quen trường cũ | P9: Hỗ trợ hòa nhập 2 tuần, buddy system
A10: THCS (Cấp 2) | B10: Chị Hoa – PH lớp 6 giai đoạn bản lề | C10: 35-48 | D10: Nữ 65% | E10: Nhân viên, công chức, kinh doanh | F10: 25-50 triệu | G10: Facebook, Google, Webinar, Forum | H10: Meta Ads, Google Ads, Webinar | I10: Sợ con sa sút vì giai đoạn dậy thì | J10: Lo trường không theo sát tâm lý HS | K10: Áp lực kết quả thi cuối cấp | L10: Tham gia webinar trước khi tour; Cần dữ liệu đầu ra | M10: Theo sát HS giai đoạn bản lề, GV chủ nhiệm tâm huyết | N10: Đăng ký webinar: Lộ trình con tôi sau lớp 5 | O10: Học phí THCS cao hơn TH nhiều | P10: ROI dài hạn: nền tảng cho lớp 10, đại học
A11: THCS (Cấp 2) | B11: Anh Minh – PH muốn con có lộ trình rõ | C11: 38-50 | D11: Nam 35% | E11: Quản lý, chuyên gia, DN | F11: 40-80 triệu | G11: Google Search, YouTube, LinkedIn | H11: Google Ads, YouTube, Webinar | I11: Muốn con có định hướng nghề nghiệp sớm | J11: Lo trường chỉ dạy lý thuyết, thiếu thực hành | K11: Muốn chương trình quốc tế/song ngữ chuẩn | L11: So sánh đầu ra, tỷ lệ đỗ THPT top, chương trình quốc tế | M11: Lộ trình 6→12 rõ ràng, chương trình Cambridge/IB option | N11: Xem lộ trình đào tạo 7 năm | O11: Trường xa nhà | P11: Xe đưa đón, kế hoạch bán trú
A12: THPT (Cấp 3) | B12: Chị Thảo – PH lớp 10 áp lực thi | C12: 38-52 | D12: Nữ 60% | E12: Nhân viên, giáo viên, kinh doanh | F12: 30-60 triệu | G12: Facebook, Google, Webinar, tìm học bổng | H12: Google Ads, Meta Ads, Webinar | I12: Lo con không đỗ trường công top | J12: Áp lực tài chính: học phí THPT tư cao | K12: Lo con không vào được đại học tốt | L12: Quyết định theo học bổng + đầu ra đại học | M12: Học bổng lên đến 100%, đầu ra ĐH top, tỷ lệ đỗ ĐH 95%+ | N12: Đăng ký thi học bổng lớp 10 | O12: Trường tư chất lượng không bằng chuyên | P12: Data đầu ra: % ĐH top, học bổng du học, IELTS
A13: THPT (Cấp 3) | B13: Anh Đức – PH chuyển trường lớp 10-11 | C13: 40-55 | D13: Nam 40% | E13: Chủ DN, quản lý cấp cao | F13: 50-100+ triệu | G13: Google Search, YouTube, referral | H13: Google Ads, Remarketing | I13: Con đang học trường không phù hợp | J13: Muốn môi trường quốc tế + du học pathway | K13: Cần chuyển nhanh, ít gián đoạn | L13: Quyết định rất nhanh khi thấy phù hợp | M13: Chuyển trường linh hoạt, nhận hồ sơ quanh năm, pathway du học | N13: Liên hệ tư vấn chuyển trường 24h | O13: Sợ con mất bạn bè | P13: Chương trình hòa nhập, buddy system, câu lạc bộ
A16: B. NỖI ĐAU KHÁCH HÀNG THEO ĐỊA ĐIỂM
A17: Địa điểm | B17: Tên cũ (trước sáp nhập) | C17: Tên mới (hiện tại) | D17: Cấp học | E17: Đặc điểm PH khu vực | F17: Nỗi đau đặc thù #1 | G17: Nỗi đau đặc thù #2 | H17: Nỗi đau đặc thù #3 | I17: Messaging phù hợp | J17: Kênh ưu tiên | K17: Đối thủ chính | L17: Lợi thế VA tại đây
A18: MN VA Gò Vấp | B18: Q. Gò Vấp, TP.HCM | C18: Q. Gò Vấp, TP.HCM | D18: MN | E18: Thu nhập trung bình-khá, đông dân, nhiều gia đình trẻ | F18: Trường MN quá tải, thiếu chỗ gửi an toàn | G18: Giao thông kẹt, cần trường gần nhà | H18: Lo bạo lực, thiếu camera giám sát | I18: An toàn #1, gần nhà, camera 24/7 | J18: Meta Ads, Zalo OA | K18: MN Sài Gòn, MN Sao Mai | L18: Flagship, CSVC mới, GV ổn định
A19: MN Nhân Lễ | B19: H. Cần Giuộc, Long An | C19: TX. Cần Giuộc, Tây Ninh | D19: MN | E19: Thu nhập trung bình, vùng KDC mới, ít lựa chọn | F19: Rất ít trường tư chất lượng trong KDC | G19: PH làm ở KCN, cần trường bán trú tốt | H19: Lo con thiếu ngoại ngữ vùng tỉnh | I19: Trường chuẩn quốc tế ngay KDC, bán trú chu đáo | J19: Zalo OA, Facebook local | K19: MN công lập địa phương | L19: Duy nhất trường tư chất lượng trong KDC
A20: MN Thái Sơn | B20: H. Cần Giuộc, Long An | C20: TX. Cần Giuộc, Tây Ninh | D20: MN+TH | E20: PH KDC Thái Sơn, thu nhập khá, mới về định cư | F20: Thiếu trường tốt gần KDC mới | G20: Muốn con có bạn bè trong khu | H20: Lo chất lượng GD vùng mới phát triển | I20: Ngay trong KDC, không cần đưa đón xa | J20: Zalo OA, Facebook group KDC | K20: MN công, MN tư nhỏ lẻ | L20: Nằm ngay trong KDC, liên cấp MN+TH
A21: MN Mekong Xanh | B21: TP. Rạch Giá, Kiên Giang | C21: TP. Rạch Giá, An Giang | D21: MN+TH | E21: PH KĐT mới, thu nhập khá, nhiều công chức/DN | F21: Ít lựa chọn trường tư trong KĐT | G21: Muốn chương trình song ngữ mà vùng tỉnh không có | H21: Lo con thua thiệt so với TP.HCM | I21: Song ngữ chuẩn TP.HCM ngay tại tỉnh | J21: Zalo OA, Facebook local, Google local | K21: Trường công lập, TT Anh ngữ | L21: Chuẩn TP.HCM, liên cấp, KĐT cao cấp
A22: TH VA Gò Vấp | B22: Q. Gò Vấp, TP.HCM | C22: Q. Gò Vấp, TP.HCM | D22: TH | E22: PH trung lưu-khá, so sánh kỹ nhiều trường | F22: Quá nhiều lựa chọn, không biết trường nào tốt | G22: Lo tiếng Anh không đủ mạnh so với international school | H22: Sĩ số lớp quá đông ở trường công | I22: Sĩ số 25, lộ trình tiếng Anh có chứng chỉ, GV 1-1 | J22: Meta Ads, Google Search | K22: TH Việt Úc, TH iSchool, TH FPT | L22: Học phí hợp lý hơn international, vẫn song ngữ chuẩn
A23: TH VA Bình Tân | B23: Q. Bình Tân, TP.HCM | C23: Q. Bình Tân, TP.HCM | D23: TH | E23: PH thu nhập trung bình, khu đông dân, công nhân + KD nhỏ | F23: Rất ít trường tư chất lượng khu vực Bình Tân | G23: Lo an ninh khu vực, muốn trường khép kín | H23: Giá phải hợp lý với thu nhập | I23: An toàn, khép kín, học phí phù hợp, bán trú tốt | J23: Meta Ads, Zalo local | K23: TH Bình Tân, TH Phước Kiểng | L23: Duy nhất trường tư song ngữ quy mô tại BT
A24: TH Thái Sơn | B24: H. Cần Giuộc, Long An | C24: TX. Cần Giuộc, Tây Ninh | D24: TH | E24: PH KDC Thái Sơn, muốn con học tại chỗ | F24: Phải đi xa để học trường tốt | G24: Lo con mệt vì di chuyển hàng ngày | H24: Chương trình tỉnh yếu hơn TP | I24: Chuẩn TP.HCM ngay KDC, không cần đi xa | J24: Zalo, Facebook local | K24: TH công lập xã | L24: Liên cấp, ngay trong KDC
A25: TH Mekong Xanh | B25: TP. Rạch Giá, Kiên Giang | C25: TP. Rạch Giá, An Giang | D25: TH | E25: PH KĐT, muốn con có nền tảng tốt | F25: Không có trường tư song ngữ tại TP Rạch Giá | G25: Muốn con thi vào trường tốt sau này | H25: Lo GV giỏi không về tỉnh dạy | I25: GV từ TP.HCM, chương trình chuẩn quốc gia + song ngữ | J25: Zalo, Facebook, Google local | K25: TH công, TT Anh ngữ | L25: Duy nhất TH tư song ngữ quy mô
A26: THCS VA Gò Vấp | B26: Q. Gò Vấp, TP.HCM | C26: Q. Gò Vấp, TP.HCM | D26: THCS | E26: PH lo lắng giai đoạn dậy thì, cần theo sát | F26: Trường công THCS sĩ số 45-50, GV không theo sát | G26: Lo con sa sút vì bạn bè tiêu cực | H26: Áp lực thi THPT cạnh tranh | I26: Sĩ số nhỏ, GV chủ nhiệm theo sát, lộ trình 6→12 | J26: Google Ads, Meta, Webinar | K26: THCS Việt Úc, THCS iSchool | L26: Liên cấp THCS-THPT, không cần thi chuyển
A27: THPT VA Gò Vấp | B27: Q. Gò Vấp, TP.HCM | C27: Q. Gò Vấp, TP.HCM | D27: THPT | E27: PH áp lực thi lớp 10, tìm giải pháp B nếu rớt công | F27: Con không đỗ trường công top → hoang mang | G27: Học phí THPT tư cao, lo tài chính | H27: Lo đầu ra đại học không tốt bằng trường chuyên | I27: Học bổng 100%, đầu ra ĐH 95%+, pathway du học | J27: Google Ads, Meta, Webinar | K27: THPT Nguyễn Khuyến, THPT Trương Vĩnh Ký | L27: Học bổng lớn, lộ trình đa dạng, tỷ lệ ĐH cao
A30: C. HÀNH TRÌNH KHÁCH HÀNG (CUSTOMER JOURNEY) THEO CẤP
A31: Giai đoạn | B31: Awareness | C31: Consideration | D31: Decision | E31: Tour/Visit | F31: Enrollment | G31: Advocacy
A32: MN | B32: Thấy ads FB/TikTok → nghe PH review → tìm Google | C32: So sánh 2-3 trường → đọc review → hỏi group | D32: Gọi hotline / Zalo → Hỏi học phí → Book tour | E32: Tour campus → gặp GV → xem phòng học → lunch trial | F32: Nộp hồ sơ → đóng cọc → nhận thông báo | G32: Review Google → giới thiệu bạn → share FB
A33: TH | B33: Tìm Google "trường TH song ngữ" → thấy ads Meta | C33: So sánh 3-5 trường → tour 2 lần → hỏi PH hiện tại | D33: Webinar/Open Day → tư vấn 1-1 → nhận ưu đãi | E33: Tour chi tiết → ngồi lớp thử → gặp GV chủ nhiệm | F33: Thi đầu vào (nếu có) → nộp hồ sơ → đóng phí | G33: Review → referral program → PH ambassador
A34: THCS | B34: Webinar "chuyển cấp" → Google "THCS tốt GV" → FB ads | C34: So sánh đầu ra → xem chương trình → hỏi alumni PH | D34: Tư vấn riêng → xem lộ trình 6→12 → học bổng | E34: Tour + ngồi lớp + gặp HS hiện tại + GV chủ nhiệm | F34: Nộp hồ sơ → phỏng vấn → đóng cọc | G34: PH chia sẻ experience → alumni success story
A35: THPT | B35: Google "tuyển sinh lớp 10" → Webinar → FB/TikTok | C35: So sánh vs công → check đầu ra ĐH → học bổng | D35: Thi học bổng → tư vấn chuyên sâu → financial plan | E35: Tour VIP → gặp BGH → xem lab/thư viện/CLB | F35: Thi tuyển/xét tuyển → nhận kết quả → enrollment | G35: Đầu ra ĐH → alumni network → PH referral

Sheet 0. Dashboard
B1: 🎯 DASHBOARD ĐIỀU HÀNH – KẾ HOẠCH TUYỂN SINH VIỆT ANH 2026
B2: Giai đoạn: 26/03/2026 – 30/09/2026 | Tổng ngân sách: 13 tỷ đồng | Mục tiêu: 1,300 học sinh
B4: 📊 KPI TỔNG QUAN (tự động liên kết từ các sheet)
B5: Chỉ số | C5: Mục tiêu | D5: Thực tế MTD | E5: Vs Target | F5: Trạng thái | G5: Nguồn dữ liệu | H5: Sheet liên kết
B6: 🏫 Nhập học tích lũy | C6: ='1. Input'!B5 -> 1300 | D6: 0 | E6: =IF(C6>0,D6/C6,0) -> 0 | F6: → Nhập tay | G6: 1. Input | H6: Nhập tay từ CRM
B7: 🎯 School Tour tích lũy | C7: ='4. Funnel'!D3 -> 1300 | D7: 0 | E7: =IF(C7>0,D7/C7,0) -> 0 | F7: → Nhập tay | G7: 4. Funnel | H7: Nhập tay từ GHL
B8: 📥 Leads tích lũy | C8: ='4. Funnel'!D4 -> 3715 | D8: 0 | E8: =IF(C8>0,D8/C8,0) -> 0 | F8: → Nhập tay | G8: 4. Funnel | H8: Nhập tay từ GHL
B9: 💰 Chi phí Paid Media | C9: ='2. Paid Media'!C10 -> 425000000 | D9: 0 | E9: =IF(C9>0,D9/C9,0) -> 0 | F9: → Nhập tay | G9: 2. Paid Media | H9: Birch / Ads Manager
B10: 📊 CPL trung bình | C10: 200000 | D10: 0 | E10: =IF(C10>0,D10/C10,0) -> 0 | F10: → Nhập tay | G10: 14. Weekly Battleplan | H10: Nhập tay tuần
B11: 🏃 Lead→Tour rate | C11: 0.3 | D11: 0 | E11: =IF(C11>0,D11/C11,0) -> 0 | F11: → Nhập tay | G11: 4. Funnel | H11: Tính từ GHL
B12: ✅ Tour→Nhập học rate | C12: 0.35 | D12: 0 | E12: =IF(C12>0,D12/C12,0) -> 0 | F12: → Nhập tay | G12: 4. Funnel | H12: Tính từ GHL
B13: ⚡ Response <5 min | C13: 0.85 | D13: 0 | E13: =IF(C13>0,D13/C13,0) -> 0 | F13: → Nhập tay | G13: 14. Weekly Battleplan | H13: Nhập tay tuần
B15: 💰 NGÂN SÁCH PAID MEDIA THEO KÊNH (liên kết 2. Paid Media)
B16: Kênh | C16: % Mix | D16: Ngân sách | E16: Vai trò | F16: CPL Mục tiêu | G16: Quản lý | H16: Ghi chú
B17: Meta / Facebook + Instagram | C17: 0.38 | D17: 3230000000 | E17: Demand + lead local | F17: 120000 | G17: Birch + GHL | H17: Kênh chủ lực
B18: Google Search | C18: 0.18 | D18: 1530000000 | E18: Intent-based | F18: 180000 | G18: Birch | H18: THCS/THPT
B19: Google Display / YouTube | C19: 0.07 | D19: 595000000 | E19: Phủ + video | F19: N/A | G19: Birch | H19: Testimonial
B20: TikTok Ads | C20: 0.1 | D20: 850000000 | E20: Video social proof | F20: 90000 | G20: Birch + GHL | H20: 100 video
B21: Zalo Ads + OA | C21: 0.07 | D21: 595000000 | E21: Nurture local | F21: 80000 | G21: GHL | H21: K12 local
B22: Webinar Ads | C22: 0.05 | D22: 425000000 | E22: Webinar lộ trình | F22: 50000 | G22: Meta + GHL | H22: THCS/THPT
B23: Remarketing đa nền tảng | C23: 0.12 | D23: 1020000000 | E23: Đuổi lại khách | F23: 150000 | G23: Birch | H23: 12%
B24: Local SEO / GMB | C24: 0.05 | D24: 425000000 | E24: Local presence | F24: N/A | G24: Manual + GHL | H24: 8 địa điểm
B25: TỔNG PAID MEDIA | C25: 1.02 | D25: 8670000000
B27: 🏫 PHÂN BỔ THEO CƠ SỞ (liên kết 3. Master Table)
B28: Cơ sở | C28: Cấp | D28: HS Mục tiêu | E28: CAC | F28: Meta (đ) | G28: G.Search (đ) | H28: TikTok (đ) | I28: Zalo (đ)
B29: MN VA Gò Vấp | C29: MN | D29: 200 | E29: 0.85 | F29: 405838877 | G29: 192239468 | H29: 106799704 | I29: 74759793
B30: MN Nhân Lễ | C30: MN | D30: 60 | E30: 0.85 | F30: 121751663 | G30: 57671840 | H30: 32039911 | I30: 22427938
B31: MN Thái Sơn | C31: MN | D31: 60 | E31: 0.85 | F31: 121751663 | G31: 57671840 | H31: 32039911 | I31: 22427938
B32: MN Mekong Xanh | C32: MN | D32: 60 | E32: 0.85 | F32: 121751663 | G32: 57671840 | H32: 32039911 | I32: 22427938
B33: TH VA Gò Vấp | C33: TH | D33: 150 | E33: 1 | F33: 358093126 | G33: 169623060 | H33: 94235033 | I33: 65964523
B34: TH VA Bình Tân | C34: TH | D34: 150 | E34: 1 | F34: 358093126 | G34: 169623060 | H34: 94235033 | I34: 65964523
B35: TH Thái Sơn | C35: TH | D35: 60 | E35: 1 | F35: 143237251 | G35: 67849224 | H35: 37694013 | I35: 26385809
B36: TH Mekong Xanh | C36: TH | D36: 60 | E36: 1 | F36: 143237251 | G36: 67849224 | H36: 37694013 | I36: 26385809
B37: THCS VA Gò Vấp | C37: THCS | D37: 200 | E37: 1.2 | F37: 572949002 | G37: 271396896 | H37: 150776053 | I37: 105543237
B38: THPT VA Gò Vấp | C38: THPT | D38: 200 | E38: 1.35 | F38: 644567627 | G38: 305321508 | H38: 169623060 | I38: 118736142
B39: Brand hệ thống | C39: Chung | D39: 100 | E39: 1 | F39: 238728751 | G39: 113082040 | H39: 62823356 | I39: 43976349
B41: 🗂️ NAVIGATOR – DANH SÁCH CÁC SHEET (Click để xem)
B42: # | C42: Tên Sheet | D42: Mô tả | E42: Dùng cho | F42: Cập nhật | G42: Tần suất | H42: Liên kết đến
B43: 1 | C43: 1. Input | D43: Thông số đầu vào toàn kế hoạch | E43: Ban điều hành | F43: 26/03 | G43: Đầu mùa | H43: Master Table, Funnel
B44: 2 | C44: 2. Paid Media | D44: Mix kênh, ngân sách, KPI mỗi kênh | E44: Marketing Lead | F44: Hàng tháng | G44: Tháng | H44: Master Table
...

Sheet 1. Input
A1: INPUT & ĐIỀU KHIỂN – BẢN V5 (BỎ PHÚ NHUẬN, CẬP NHẬT ĐỊA GIỚI)
A2: ⚠️ Phú Nhuận ĐÃ BỎ. Ngân sách phân bổ lại cho các cơ sở còn lại. Cần Giuộc → Tây Ninh. Rạch Giá → An Giang.
A3: Hạng mục | B3: Giá trị | C3: Đơn vị | D3: Ghi chú
A4: Tổng ngân sách | B4: 13000000000 | C4: đ | D4: 13 tỷ
A5: Mục tiêu nhập học | B5: 1300 | C5: HS | D5: Không còn Phú Nhuận → phân bổ lại
A6: NC → Lead | B6: 0.2 | C6: % | D6: Benchmark K12: 18-25%
A7: Lead → School Tour | B7: 0.3 | C7: % | D7: SLA < 5 phút + GHL automation
A8: Tour → Nhập học | B8: 0.35 | C8: % | D8: Thực tế K12 VN
A9: CRM / GoHighLevel | B9: 200000000 | C9: đ | D9: GHL + Zalo + SMS + landing
A10: School Tour / Open Day / Event | B10: 800000000 | C10: đ | D10: Điểm chuyển đổi #1
A11: Nhân sự Sales | B11: 800000000 | C11: đ | D11: Lương + KPI + hoa hồng
A12: Content / Brand / Sales Enablement | B12: 700000000 | C12: đ | D12: Kho sẵn + creative mới
A13: Nhân sự Marketing (5 người × 6T) | B13: 450000000 | C13: đ | D13: 5 người × 6 tháng × 15 triệu
A14: Học bổng / Promotion | B14: 1000000000 | C14: đ | D14: Kích hoạt quyết định
A15: Paid Media | B15: 8500000000 | C15: đ | D15: 65.4% tổng NS
A16: Training / QA / Data / Mystery call | B16: 550000000 | C16: đ | D16: 100+100+200+150 triệu
A18: KIỂM TRA | B18: =SUM(B9:B16) -> 13000000000
A19: Chênh lệch | B19: =B4-B18 -> 0
A20: Trạng thái | B20: =IF(ABS(B19)<1000,"✅ Khớp 13 tỷ","❌ LỆCH") -> ✅ Khớp 13 tỷ
A22: CHI TIẾT BỔ SUNG
A23: Số cơ sở | B23: 6 | C23: cơ sở | D23: Bỏ Phú Nhuận, còn 6 cơ sở hoạt động
A24: Số cấp học | B24: 4 | C24: cấp | D24: MN, TH, THCS, THPT
A25: Số LP cần tạo | B25: 8 | C25: trang | D25: 1 LP/campus + 1 webinar + 1 tỉnh MN + 1 tỉnh TH
A26: Số pipeline GHL | B26: 4 | C26: pipeline | D26: MN, TH, THCS, THPT
A27: Thời gian chiến dịch | B27: 7 | C27: tháng | D27: 26/03 - 30/09/2026
A28: Số tuần tác chiến | B28: 28 | C28: tuần | D28: Tuần 1 (26/03) → Tuần 28 (30/09)
A29: Số nhân sự Marketing | B29: 5 | C29: người | D29: PM×1, Content×2, Performance×1, CRM×1
A30: Số nhân sự Sales | B30: 6 | C30: người | D30: 1 Sales Lead + 5 Tư vấn viên (round-robin)
A31: Kho content sẵn có | B31: 2000 | C31: bài | D31: Ảnh+video+bài viết kho cũ
A32: Video testimonial | B32: 100 | C32: video | D32: Kho 100 video PH+HS+GV sẵn sàng
A33: Webinar planned | B33: 8 | C33: buổi | D33: 6 chính + 2 bổ sung
A34: Open Day planned | B34: 2 | C34: sự kiện | D34: Tháng 5 + Tháng 6
A35: Lead response SLA | B35: 5 | C35: phút | D35: Gọi lại trong 5 phút, mục tiêu 85%
A36: Benchmark NC→Lead | B36: 18-25% | C36: % | D36: K12 VN trung bình
A37: Benchmark Lead→Tour | B37: 25-35% | C37: % | D37: Cần SLA tốt + GHL automation
A38: Benchmark Tour→Enroll | B38: 30-40% | C38: % | D38: Phụ thuộc tour quality + follow-up
A40: DANH SÁCH CƠ SỞ (ĐỊA GIỚI MỚI + CŨ)
A41: STT | B41: Tên cơ sở | C41: Cấp | D41: Địa chỉ | E41: Khu vực mới | F41: Khu vực cũ (trước sáp nhập) | G41: Hotline
A42: 1 | B42: MN VA Gò Vấp | C42: MN | D42: 573 Đ. Lê Đức Thọ, P. An Hội Tây | E42: Q. Gò Vấp, TP.HCM | F42: Q. Gò Vấp, TP.HCM (không đổi) | G42: 0916 961 409
A43: 2 | B43: MN Nhân Lễ | C43: MN | D43: 22 Đường D2, KDC Cần Giuộc | E43: TX. Cần Giuộc, tỉnh Tây Ninh | F43: H. Cần Giuộc, tỉnh Long An | G43: 0916 961 409
...

Sheet 2. Paid Media
A1: MIX KÊNH PAID MEDIA – 8.5 TỶ (TÁCH SEARCH/DISPLAY, KHÔNG CÓ PHÚ NHUẬN)
A2: Kênh | B2: % Mix | C2: Ngân sách | D2: Vai trò | E2: KPI | F2: CPL mục tiêu | G2: Quản lý bởi | H2: Ghi chú
A3: Meta / Facebook + Instagram | B3: 0.38 | C3: =B3*'1. Input'!B15 -> 3230000000 | D3: Demand + lead local | E3: CPL, Volume | F3: 120000 | G3: Birch + GHL | H3: Kênh chủ lực
A4: Google Search (TÁCH RIÊNG) | B4: 0.18 | C4: =B4*'1. Input'!B15 -> 1530000000 | D4: Intent-based | E4: CPC, Quality | F4: 180000 | G4: Birch | H4: Đo riêng THCS/THPT
A5: Google Display / YouTube | B5: 0.07 | C5: =B5*'1. Input'!B15 -> 595000000 | D5: Phủ + video | E5: CPM, View | G5: Birch | H5: Testimonial 15-30s
A6: TikTok Ads | B6: 0.1 | C6: =B6*'1. Input'!B15 -> 850000000 | D6: Video social proof | E6: CPV, Lead | F6: 90000 | G6: Birch + GHL | H6: 100 video = vàng
A7: Zalo Ads + OA | B7: 0.07 | C7: =B7*'1. Input'!B15 -> 595000000 | D7: Nurture local | E7: Open, CTR | F7: 80000 | G7: GoHighLevel | H7: Hidden champion K12
A8: Webinar Ads (THCS/THPT) | B8: 0.05 | C8: =B8*'1. Input'!B15 -> 425000000 | D8: Webinar lộ trình | E8: Đăng ký | F8: 50000 | G8: Meta + GHL | H8: KHÔNG cho MN/TH
A9: Remarketing đa nền tảng | B9: 0.12 | C9: =B9*'1. Input'!B15 -> 1020000000 | D9: Đuổi lại khách | E9: ROAS, Conv | F9: 150000 | G9: Birch | H9: Giảm 15%→12%
A10: Local SEO / Google Business | B10: 0.05 | C10: =B10*'1. Input'!B15 -> 425000000 | D10: Local presence | E10: Map, Clicks | G10: Manual + GHL | H10: 8 địa điểm
A11: TỔNG | B11: =SUM(B3:B10) -> 1.02 | C11: =SUM(C3:C10) -> 8670000000
A13: NGÂN SÁCH PAID MEDIA THEO THÁNG
A14: Kênh | B14: T4 (12%) | C14: T5 (24%) | D14: T6 (28%) | E14: T7 (24%) | F14: T8 (8%) | G14: T9 (2%) | H14: Tổng 7 tháng
A15: Meta / FB+IG | B15: =0.12*C3 -> 387600000 | C15: =0.24*C3 -> 775200000 | D15: =0.28*C3 -> 904400000 | E15: =0.24*C3 -> 775200000 | F15: =0.08*C3 -> 258400000 | G15: =0.02*C3 -> 64600000 | H15: =SUM(B15:G15) -> 3165400000
A16: Google Search | B16: =0.12*C4 -> 183600000 | C16: =0.24*C4 -> 367200000 | D16: =0.28*C4 -> 428400000 | E16: =0.24*C4 -> 367200000 | F16: =0.08*C4 -> 122400000 | G16: =0.02*C4 -> 30600000 | H16: =SUM(B16:G16) -> 1499400000
A17: Google Display/YT | B17: =0.12*C5 -> 71400000 | C17: =0.24*C5 -> 142800000 | D17: =0.28*C5 -> 166600000 | E17: =0.24*C5 -> 142800000 | F17: =0.08*C5 -> 47600000 | G17: =0.02*C5 -> 11900000 | H17: =SUM(B17:G17) -> 583100000
A18: TikTok Ads | B18: =0.12*C6 -> 102000000 | C18: =0.24*C6 -> 204000000 | D18: =0.28*C6 -> 238000000 | E18: =0.24*C6 -> 204000000 | F18: =0.08*C6 -> 68000000 | G18: =0.02*C6 -> 17000000 | H18: =SUM(B18:G18) -> 833000000
A19: Zalo Ads+OA | B19: =0.12*C7 -> 71400000 | C19: =0.24*C7 -> 142800000 | D19: =0.28*C7 -> 166600000 | E19: =0.24*C7 -> 142800000 | F19: =0.08*C7 -> 47600000 | G19: =0.02*C7 -> 11900000 | H19: =SUM(B19:G19) -> 583100000
A20: Webinar Ads | B20: =0.12*C8 -> 51000000 | C20: =0.24*C8 -> 102000000 | D20: =0.28*C8 -> 119000000 | E20: =0.24*C8 -> 102000000 | F20: =0.08*C8 -> 34000000 | G20: =0.02*C8 -> 8500000 | H20: =SUM(B20:G20) -> 416500000
A21: Remarketing | B21: =0.12*C9 -> 122400000 | C21: =0.24*C9 -> 244800000 | D21: =0.28*C9 -> 285600000 | E21: =0.24*C9 -> 244800000 | F21: =0.08*C9 -> 81600000 | G21: =0.02*C9 -> 20400000 | H21: =SUM(B21:G21) -> 999600000
A22: Local SEO/GMB | B22: =0.12*C10 -> 51000000 | C22: =0.24*C10 -> 102000000 | D22: =0.28*C10 -> 119000000 | E22: =0.24*C10 -> 102000000 | F22: =0.08*C10 -> 34000000 | G22: =0.02*C10 -> 8500000 | H22: =SUM(B22:G22) -> 416500000
A24: CHI TIẾT VAI TRÒ TỪNG KÊNH
A25: Kênh | B25: Vai trò trong funnel | C25: Giai đoạn KH | D25: Resource cần | E25: Daily operations | F25: Weekly optimization | G25: Tool chính
A26: Meta Ads | B26: Demand generation + Lead local + Social proof | C26: Awareness → Consideration | D26: 30+ creative (image+video), 12 audiences | E26: Check CPL, scale/pause, creative refresh | F26: A/B test creative, audience expansion, budget realloc | G26: Meta Ads Manager + Birch
A27: Google Search | B27: Intent-based capture + Brand defense | C27: Consideration → Decision | D27: 20 campaigns, 200+ keywords, 15 RSA | E27: Search terms review, bid adjust, QS check | F27: Negative KW update, RSA test, campaign restructure | G27: Google Ads + Birch
A28: Google Display/YT | B28: Awareness phủ + Video retarget | C28: Awareness + Remarketing | D28: 5 display banners, 3 video 15-30s | E28: Check CPM, placement exclusion | F28: Placement review, video performance | G28: Google Ads + Birch
A29: TikTok Ads | B29: Video social proof + Gen Z/Millennial reach | C29: Awareness → Lead | D29: 100 video kho sẵn, 5 new/tháng | E29: Check CPV, engagement, 3s retention | F29: Video performance ranking, upload new | G29: TikTok Ads + Birch
A30: Zalo Ads+OA | B30: Local nurture + Broadcast + Remarketing | C30: Consideration → Decision | D30: 8 broadcast templates, 4 ad creatives | E30: Check OA messages, broadcast schedule | F30: Segment refresh, broadcast content planning | G30: Zalo Ads + GHL
A31: Webinar Ads | B31: Education + Trust building + Conversion | C31: Consideration → Decision | D31: LP webinar, email sequence, Zoom setup | E31: Monitor registrations, reminder blast | F31: Post-webinar analysis, follow-up sequence | G31: Meta + Google + GHL
A32: Remarketing | B32: Re-engage warm/hot leads across platforms | C32: Decision → Conversion | D32: Dynamic creative, countdown, offers | E32: Check frequency, exclude converted | F32: Audience refresh, creative rotation | G32: All platforms + Birch
A33: Local SEO/GMB | B33: Local presence + Map visibility + Reviews | C33: Awareness (local) | D33: Ảnh, posts, review management | E33: Reply reviews, check listing accuracy | F33: Post 1 bài/tuần, update photos | G33: Google Business + Manual

Sheet 3. Master Table
A1: PHÂN BỔ – BỎ PHÚ NHUẬN – 11 DÒNG CƠ SỞ (Cần Giuộc→Tây Ninh, Rạch Giá→An Giang)
A2: Cấp | B2: Địa điểm | C2: Địa chỉ / Tỉnh | D2: HS | E2: CAC | F2: Điểm | G2: % | H2: Tổng NS | I2: Paid | J2: Tour | K2: Meta | L2: G.Search | M2: G.Display | N2: TikTok | O2: Zalo | P2: Webinar | Q2: Remarket | R2: Local SEO
A3: MN | B3: MN VA Gò Vấp | C3: 573 Lê Đức Thọ, Gò Vấp, TP.HCM | D3: 200 | E3: 0.85 | F3: =D3*E3 -> 170 | G3: =F3/F$14 -> 0.12564671 | H3: =G3*'1. Input'!B4 -> 1.6334072e+09 | I3: =G3*'1. Input'!B15 -> 1.067997e+09 | J3: =G3*'1. Input'!B10 -> 1.0051737e+08 | K3: =I3*'2. Paid Media'!B3 -> 4.0583888e+08 | L3: =I3*'2. Paid Media'!B4 -> 1.9223947e+08 | M3: =I3*'2. Paid Media'!B5 -> 74759793 | N3: =I3*'2. Paid Media'!B6 -> 1.067997e+08 | O3: =I3*'2. Paid Media'!B7 -> 74759793 | P3: =I3*'2. Paid Media'!B8 -> 53399852 | Q3: =I3*'2. Paid Media'!B9 -> 1.2815965e+08 | R3: =I3*'2. Paid Media'!B10 -> 53399852
A4: MN | B4: MN Nhân Lễ | C4: 22 D2, KDC Cần Giuộc, Tây Ninh | D4: 60 | E4: 0.85 | F4: =D4*E4 -> 51 | G4: =F4/F$14 -> 0.037694013 | H4: =G4*'1. Input'!B4 -> 4.9002217e+08 | I4: =G4*'1. Input'!B15 -> 3.2039911e+08 | J4: =G4*'1. Input'!B10 -> 30155211 | K4: =I4*'2. Paid Media'!B3 -> 1.2175166e+08 | L4: =I4*'2. Paid Media'!B4 -> 57671840 | M4: =I4*'2. Paid Media'!B5 -> 22427938 | N4: =I4*'2. Paid Media'!B6 -> 32039911 | O4: =I4*'2. Paid Media'!B7 -> 22427938 | P4: =I4*'2. Paid Media'!B8 -> 16019956 | Q4: =I4*'2. Paid Media'!B9 -> 38447894 | R4: =I4*'2. Paid Media'!B10 -> 16019956
A5: MN | B5: MN Thái Sơn | C5: KDC Thái Sơn, Cần Giuộc, Tây Ninh | D5: 60 | E5: 0.85 | F5: =D5*E5 -> 51 | G5: =F5/F$14 -> 0.037694013 | H5: =G5*'1. Input'!B4 -> 4.9002217e+08 | I5: =G5*'1. Input'!B15 -> 3.2039911e+08 | J5: =G5*'1. Input'!B10 -> 30155211 | K5: =I5*'2. Paid Media'!B3 -> 1.2175166e+08 | L5: =I5*'2. Paid Media'!B4 -> 57671840 | M5: =I5*'2. Paid Media'!B5 -> 22427938 | N5: =I5*'2. Paid Media'!B6 -> 32039911 | O5: =I5*'2. Paid Media'!B7 -> 22427938 | P5: =I5*'2. Paid Media'!B8 -> 16019956 | Q5: =I5*'2. Paid Media'!B9 -> 38447894 | R5: =I5*'2. Paid Media'!B10 -> 16019956
A6: MN | B6: MN Mekong Xanh | C6: Lô E7, KĐT Tây Bắc, Rạch Giá, An Giang | D6: 60 | E6: 0.85 | F6: =D6*E6 -> 51 | G6: =F6/F$14 -> 0.037694013 | H6: =G6*'1. Input'!B4 -> 4.9002217e+08 | I6: =G6*'1. Input'!B15 -> 3.2039911e+08 | J6: =G6*'1. Input'!B10 -> 30155211 | K6: =I6*'2. Paid Media'!B3 -> 1.2175166e+08 | L6: =I6*'2. Paid Media'!B4 -> 57671840 | M6: =I6*'2. Paid Media'!B5 -> 22427938 | N6: =I6*'2. Paid Media'!B6 -> 32039911 | O6: =I6*'2. Paid Media'!B7 -> 22427938 | P6: =I6*'2. Paid Media'!B8 -> 16019956 | Q6: =I6*'2. Paid Media'!B9 -> 38447894 | R6: =I6*'2. Paid Media'!B10 -> 16019956
A7: TH | B7: TH VA Gò Vấp | C7: 160/72 Phan Huy Ích, Gò Vấp, TP.HCM | D7: 150 | E7: 1 | F7: =D7*E7 -> 150 | G7: =F7/F$14 -> 0.11086475 | H7: =G7*'1. Input'!B4 -> 1.4412417e+09 | I7: =G7*'1. Input'!B15 -> 9.4235033e+08 | J7: =G7*'1. Input'!B10 -> 88691796 | K7: =I7*'2. Paid Media'!B3 -> 3.5809313e+08 | L7: =I7*'2. Paid Media'!B4 -> 1.6962306e+08 | M7: =I7*'2. Paid Media'!B5 -> 65964523 | N7: =I7*'2. Paid Media'!B6 -> 94235033 | O7: =I7*'2. Paid Media'!B7 -> 65964523 | P7: =I7*'2. Paid Media'!B8 -> 47117517 | Q7: =I7*'2. Paid Media'!B9 -> 1.1308204e+08 | R7: =I7*'2. Paid Media'!B10 -> 47117517
A8: TH | B8: TH VA Bình Tân | C8: Số 7 đường 38A, Tân Tạo, Bình Tân, TP.HCM | D8: 150 | E8: 1 | F8: =D8*E8 -> 150 | G8: =F8/F$14 -> 0.11086475 | H8: =G8*'1. Input'!B4 -> 1.4412417e+09 | I8: =G8*'1. Input'!B15 -> 9.4235033e+08 | J8: =G8*'1. Input'!B10 -> 88691796 | K8: =I8*'2. Paid Media'!B3 -> 3.5809313e+08 | L8: =I8*'2. Paid Media'!B4 -> 1.6962306e+08 | M8: =I8*'2. Paid Media'!B5 -> 65964523 | N8: =I8*'2. Paid Media'!B6 -> 94235033 | O8: =I8*'2. Paid Media'!B7 -> 65964523 | P8: =I8*'2. Paid Media'!B8 -> 47117517 | Q8: =I8*'2. Paid Media'!B9 -> 1.1308204e+08 | R8: =I8*'2. Paid Media'!B10 -> 47117517
A9: TH | B9: TH Thái Sơn | C9: KDC Thái Sơn, Cần Giuộc, Tây Ninh | D9: 60 | E9: 1 | F9: =D9*E9 -> 60 | G9: =F9/F$14 -> 0.044345898 | H9: =G9*'1. Input'!B4 -> 5.7649667e+08 | I9: =G9*'1. Input'!B15 -> 3.7694013e+08 | J9: =G9*'1. Input'!B10 -> 35476718 | K9: =I9*'2. Paid Media'!B3 -> 1.4323725e+08 | L9: =I9*'2. Paid Media'!B4 -> 67849224 | M9: =I9*'2. Paid Media'!B5 -> 26385809 | N9: =I9*'2. Paid Media'!B6 -> 37694013 | O9: =I9*'2. Paid Media'!B7 -> 26385809 | P9: =I9*'2. Paid Media'!B8 -> 18847007 | Q9: =I9*'2. Paid Media'!B9 -> 45232816 | R9: =I9*'2. Paid Media'!B10 -> 18847007
A10: TH | B10: TH Mekong Xanh | C10: Lô E7, KĐT Tây Bắc, Rạch Giá, An Giang | D10: 60 | E10: 1 | F10: =D10*E10 -> 60 | G10: =F10/F$14 -> 0.044345898 | H10: =G10*'1. Input'!B4 -> 5.7649667e+08 | I10: =G10*'1. Input'!B15 -> 3.7694013e+08 | J10: =G10*'1. Input'!B10 -> 35476718 | K10: =I10*'2. Paid Media'!B3 -> 1.4323725e+08 | L10: =I10*'2. Paid Media'!B4 -> 67849224 | M10: =I10*'2. Paid Media'!B5 -> 26385809 | N10: =I10*'2. Paid Media'!B6 -> 37694013 | O10: =I10*'2. Paid Media'!B7 -> 26385809 | P10: =I10*'2. Paid Media'!B8 -> 18847007 | Q10: =I10*'2. Paid Media'!B9 -> 45232816 | R10: =I10*'2. Paid Media'!B10 -> 18847007
A11: THCS | B11: THCS VA Gò Vấp | C11: 160/72 Phan Huy Ích, Gò Vấp, TP.HCM | D11: 200 | E11: 1.2 | F11: =D11*E11 -> 240 | G11: =F11/F$14 -> 0.17738359 | H11: =G11*'1. Input'!B4 -> 2.3059867e+09 | I11: =G11*'1. Input'!B15 -> 1.5077605e+09 | J11: =G11*'1. Input'!B10 -> 1.4190687e+08 | K11: =I11*'2. Paid Media'!B3 -> 5.72949e+08 | L11: =I11*'2. Paid Media'!B4 -> 2.713969e+08 | M11: =I11*'2. Paid Media'!B5 -> 1.0554324e+08 | N11: =I11*'2. Paid Media'!B6 -> 1.5077605e+08 | O11: =I11*'2. Paid Media'!B7 -> 1.0554324e+08 | P11: =I11*'2. Paid Media'!B8 -> 75388027 | Q11: =I11*'2. Paid Media'!B9 -> 1.8093126e+08 | R11: =I11*'2. Paid Media'!B10 -> 75388027
A12: THPT | B12: THPT VA Gò Vấp | C12: 160/72 Phan Huy Ích, Gò Vấp, TP.HCM | D12: 200 | E12: 1.35 | F12: =D12*E12 -> 270 | G12: =F12/F$14 -> 0.19955654 | H12: =G12*'1. Input'!B4 -> 2.594235e+09 | I12: =G12*'1. Input'!B15 -> 1.6962306e+09 | J12: =G12*'1. Input'!B10 -> 1.5964523e+08 | K12: =I12*'2. Paid Media'!B3 -> 6.4456763e+08 | L12: =I12*'2. Paid Media'!B4 -> 3.0532151e+08 | M12: =I12*'2. Paid Media'!B5 -> 1.1873614e+08 | N12: =I12*'2. Paid Media'!B6 -> 1.6962306e+08 | O12: =I12*'2. Paid Media'!B7 -> 1.1873614e+08 | P12: =I12*'2. Paid Media'!B8 -> 84811530 | Q12: =I12*'2. Paid Media'!B9 -> 2.0354767e+08 | R12: =I12*'2. Paid Media'!B10 -> 84811530
A13: Liên cấp | B13: Brand hệ thống | C13: Retarget + brand awareness chung | D13: 100 | E13: 1 | F13: =D13*E13 -> 100 | G13: =F13/F$14 -> 0.07390983 | H13: =G13*'1. Input'!B4 -> 9.6082779e+08 | I13: =G13*'1. Input'!B15 -> 6.2823356e+08 | J13: =G13*'1. Input'!B10 -> 59127864 | K13: =I13*'2. Paid Media'!B3 -> 2.3872875e+08 | L13: =I13*'2. Paid Media'!B4 -> 1.1308204e+08 | M13: =I13*'2. Paid Media'!B5 -> 43976349 | N13: =I13*'2. Paid Media'!B6 -> 62823356 | O13: =I13*'2. Paid Media'!B7 -> 43976349 | P13: =I13*'2. Paid Media'!B8 -> 31411678 | Q13: =I13*'2. Paid Media'!B9 -> 75388027 | R13: =I13*'2. Paid Media'!B10 -> 31411678
A14: TỔNG | D14: =SUM(D3:D13) -> 1300 | F14: =SUM(F3:F13) -> 1353 | G14: =SUM(G3:G13) -> 1 | H14: =SUM(H3:H13) -> 13000000000 | I14: =SUM(I3:I13) -> 8500000000 | J14: =SUM(J3:J13) -> 800000000 | K14: =SUM(K3:K13) -> 3230000000 | L14: =SUM(L3:L13) -> 1530000000 | M14: =SUM(M3:M13) -> 595000000 | ... R14: =SUM(R3:R13) -> 425000000

Sheet 4. Funnel
A1: FUNNEL & KPI (NC→Lead 20% | Lead→Tour 30% | Tour→Nhập 35%)
A2: Tầng | B2: Tỷ lệ | C2: Nguồn | D2: Sản lượng | E2: Chi phí BQ | F2: Ghi chú
A3: Nhập học | D3: ='1. Input'!B5 -> 1300 | E3: =ROUND('1. Input'!B4/D3,0) -> 10000000 | F3: 1,300 HS mục tiêu
A4: School Tour | B4: ='1. Input'!B8 -> 0.35 | D4: =ROUNDUP(D3/B4,0) -> 3715 | E4: =ROUND('1. Input'!B4/D4,0) -> 3499327
A5: Leads | B5: ='1. Input'!B7 -> 0.3 | D5: =ROUNDUP(D4/B5,0) -> 12384 | E5: =ROUND('1. Input'!B4/D5,0) -> 1049742
A6: New Contacts | B6: ='1. Input'!B6 -> 0.2 | D6: =ROUNDUP(D5/B6,0) -> 61920 | E6: =ROUND('1. Input'!B4/D6,0) -> 209948
A8: B. FUNNEL THEO CẤP HỌC
A9: Cấp | B9: New Contacts | C9: NC→Lead % | D9: Leads | E9: Lead→Tour % | F9: Tours | G9: Tour→Enroll % | H9: Enrolled | I9: CPL mục tiêu | J9: Cost/Tour | K9: CAC | L9: Ghi chú
A10: MN (4 cơ sở) | B10: 9524 | C10: 20% | D10: 1905 | E10: 32% | F10: 610 | G10: 37% | H10: 380 | I10: 100000 | J10: 500000 | K10: 8500000 | L10: Conversion cao nhất, CAC thấp
A11: TH (4 cơ sở) | B11: 10000 | C11: 20% | D11: 2000 | E11: 30% | F11: 600 | G11: 35% | H11: 420 | I11: 120000 | J11: 700000 | K11: 10000000 | L11: Volume lớn, spread 4 campus
A12: THCS (1 cơ sở) | B12: 4762 | C12: 20% | D12: 952 | E12: 28% | F12: 267 | G12: 33% | H12: 200 | I12: 160000 | J12: 1500000 | K12: 12000000 | L12: Higher intent, cần webinar
A13: THPT (1 cơ sở) | B13: 3810 | C13: 20% | D13: 762 | E13: 26% | F13: 198 | G13: 30% | H13: 200 | I13: 180000 | J13: 2000000 | K13: 13500000 | L13: Học bổng + webinar = key
A14: Brand/Chung | B14: 2381 | C14: 20% | D14: 476 | E14: 25% | F14: 119 | G14: 28% | H14: 100 | I14: 200000 | J14: - | K14: - | L14: Hỗ trợ brand, không đo CAC riêng
A17: C. FUNNEL THEO ĐỊA ĐIỂM (CƠ SỞ)
A18: Cơ sở | B18: Cấp | C18: Khu vực mới (cũ) | D18: HS mục tiêu | E18: Leads cần | F18: Tours cần | G18: Lead→Tour target | H18: Tour→Enroll target | I18: Kênh chính | J18: Độ khó | K18: Ghi chú
A19: MN VA Gò Vấp | B19: MN | C19: Gò Vấp, TP.HCM | D19: 200 | E19: 1905 | F19: 610 | G19: 32% | H19: 37% | I19: Meta + Zalo | J19: Trung bình | K19: Flagship, brand mạnh
A20: MN Nhân Lễ | B20: MN | C20: TX. Cần Giuộc, Tây Ninh (cũ: H. Cần Giuộc, Long An) | D20: 60 | E20: 572 | F20: 183 | G20: 32% | H20: 37% | I20: Zalo + Facebook local | J20: Khó | K20: Thị trường nhỏ, cần local trust
A21: MN Thái Sơn | B21: MN | C21: TX. Cần Giuộc, Tây Ninh (cũ: H. Cần Giuộc, Long An) | D21: 60 | E21: 572 | F21: 183 | G21: 32% | H21: 37% | I21: Zalo + Facebook local | J21: Khó | K21: KDC nhỏ, cần word-of-mouth
A22: MN Mekong Xanh | B22: MN | C22: TP. Rạch Giá, An Giang (cũ: TP. Rạch Giá, Kiên Giang) | D22: 60 | E22: 572 | F22: 183 | G22: 32% | H22: 37% | I22: Zalo + Google local | J22: Rất khó | K22: Thị trường mới, chưa có brand
A23: TH VA Gò Vấp | B23: TH | C23: Gò Vấp, TP.HCM | D23: 150 | E23: 1429 | F23: 429 | G23: 30% | H23: 35% | I23: Meta + Google | J23: Trung bình | K23: Cạnh tranh cao với Việt Úc, iSchool
A24: TH VA Bình Tân | B24: TH | C24: Bình Tân, TP.HCM | D24: 150 | E24: 1429 | F24: 429 | G24: 30% | H24: 35% | I24: Meta + Zalo | J24: Dễ-TB | K24: Ít đối thủ tư thục tại BT
A25: TH Thái Sơn | B25: TH | C25: TX. Cần Giuộc, Tây Ninh (cũ: H. Cần Giuộc, Long An) | D25: 60 | E25: 572 | F25: 171 | G25: 30% | H25: 35% | I25: Zalo + Facebook | J25: Khó | K25: Thị trường nhỏ
A26: TH Mekong Xanh | B26: TH | C26: TP. Rạch Giá, An Giang (cũ: TP. Rạch Giá, Kiên Giang) | D26: 60 | E26: 572 | F26: 171 | G26: 30% | H26: 35% | I26: Zalo + Google local | J26: Rất khó | K26: Mới, chưa có track record
A27: THCS VA Gò Vấp | B27: THCS | C27: Gò Vấp, TP.HCM | D27: 200 | E27: 2858 | F27: 800 | G27: 28% | H27: 33% | I27: Google + Meta + Webinar | J27: Cao | K27: Webinar là key, giai đoạn bản lề
A28: THPT VA Gò Vấp | B28: THPT | C28: Gò Vấp, TP.HCM | D28: 200 | E28: 2540 | F28: 660 | G28: 26% | H28: 30% | I28: Google + Meta + Webinar | J28: Rất cao | K28: Cần học bổng + đầu ra ĐH + webinar
A29: Brand hệ thống | B29: Liên cấp | C29: Tất cả | D29: 100 | E29: 1429 | F29: 357 | G29: 25% | H29: 28% | I29: Remarketing + Brand | J29: - | K29: Hỗ trợ toàn bộ funnel

Sheet 5. Google Ads Chi Tiết
A1: KẾ HOẠCH GOOGLE ADS – CẤU TRÚC TÀI KHOẢN + CAMPAIGN + KEYWORD + RSA + BIRCH
A3: A. CẤU TRÚC TÀI KHOẢN GOOGLE ADS
A4: Cấp độ | B4: Tên | C4: Mô tả | D4: Ngân sách | E4: Ghi chú
A5: Account | B5: VA_TuyenSinh_2026 | C5: Tài khoản chính cho tuyển sinh | D5: ='1. Input'!B15*0.25 -> 2125000000 | E5: Tổng Google = 25% Paid Media
A6: Campaign | B6: S_BRAND_System | C6: Brand search toàn hệ thống | D6: Auto | E6: Luôn bật, không pause
A7: Campaign | B7: S_MN_GV_Generic | C7: Search mầm non Gò Vấp generic | D7: Daily cap | E7: Keyword: mầm non song ngữ gò vấp
A8: Campaign | B8: S_MN_GV_HighIntent | C8: Search mầm non Gò Vấp high intent | D8: Daily cap | E8: Keyword: học phí mầm non, tuyển sinh mầm non
A9: Campaign | B9: S_MN_Tinh_Generic | C9: Search mầm non tỉnh (Tây Ninh, An Giang) | D9: Daily cap | E9: Local intent tỉnh
A10: Campaign | B10: S_TH_GV_Generic | C10: Search tiểu học Gò Vấp | D10: Daily cap | E10: Lớp 1, song ngữ, học phí
A11: Campaign | B11: S_TH_BT_Generic | C11: Search tiểu học Bình Tân | D11: Daily cap | E11: Local + song ngữ
A12: Campaign | B12: S_TH_Tinh_Generic | C12: Search tiểu học tỉnh | D12: Daily cap | E12: Thái Sơn + Mekong Xanh
A13: Campaign | B13: S_THCS_GV_Generic | C13: Search THCS Gò Vấp generic | D13: Daily cap | E13: Lớp 6, trường cấp 2
A14: Campaign | B14: S_THCS_GV_HighIntent | C14: Search THCS Gò Vấp high intent | D14: Daily cap | E14: Tuyển sinh lớp 6, học phí
A15: Campaign | B15: S_THPT_GV_Generic | C15: Search THPT Gò Vấp generic | D15: Daily cap | E15: Lớp 10, trường cấp 3
A16: Campaign | B16: S_THPT_GV_HighIntent | C16: Search THPT Gò Vấp high intent | D16: Daily cap | E16: Tuyển sinh lớp 10, học bổng
A17: Campaign | B17: S_THPT_GV_Webinar | C17: Search THPT webinar | D17: Daily cap | E17: Hội thảo, lộ trình, chọn trường
... A24: Campaign | B24: PMAX_Test | C24: Performance Max test | D24: Daily cap 2% | E24: Chỉ test từ T6, không scale sớm
A26: B. KEYWORD BANK (EXACT + PHRASE)
A27: Cấp | B27: Nhóm | C27: Match | D27: Keyword | E27: Campaign | F27: Ghi chú
A28: MN | B28: Brand | C28: Exact | D28: [trường mầm non việt anh gò vấp] | E28: S_BRAND
A29: MN | B29: Brand | C29: Exact | D29: [mầm non việt anh lê đức thọ] | E29: S_BRAND
A30: MN | B30: Generic | C30: Exact | D30: [trường mầm non song ngữ gò vấp] | E30: S_MN_GV_Generic | F30: Top KW
A31: MN | B31: Generic | C31: Exact | D31: [trường mầm non tư thục gò vấp] | E31: S_MN_GV_Generic
A32: MN | B32: Generic | C32: Phrase | D32: "trường mầm non gần nhà" | E32: S_MN_GV_Generic | F32: Local
A33: MN | B33: Generic | C33: Phrase | D33: "mầm non song ngữ" | E33: S_MN_GV_Generic
A34: MN | B34: HighIntent | C34: Exact | D34: [học phí mầm non song ngữ gò vấp] | E34: S_MN_GV_HighIntent | F34: HOT
A35: MN | B35: HighIntent | C35: Exact | D35: [tuyển sinh mầm non gò vấp] | E35: S_MN_GV_HighIntent | F35: HOT
A36: MN | B36: Pain | C36: Phrase | D36: "trường mầm non an toàn" | E36: S_MN_GV_Generic
A37: MN | B37: Pain | C37: Phrase | D37: "trường mầm non có camera" | E37: S_MN_GV_Generic
A38: TH | B38: Brand | C38: Exact | D38: [trường việt anh gò vấp] | E38: S_BRAND
A39: TH | B39: Brand | C39: Exact | D39: [trường việt anh bình tân] | E39: S_BRAND
A40: TH | B40: Generic | C40: Exact | D40: [trường tiểu học song ngữ gò vấp] | E40: S_TH_GV_Generic
A41: TH | B41: Generic | C41: Exact | D41: [trường tiểu học tư thục bình tân] | E41: S_TH_BT_Generic
A42: TH | B42: HighIntent | C42: Exact | D42: [tuyển sinh lớp 1 trường tư] | E42: S_TH_GV_HighIntent | F42: HOT
A43: TH | B43: HighIntent | C43: Exact | D43: [học phí tiểu học song ngữ] | E43: S_TH_GV_HighIntent | F43: HOT
A44: THCS | B44: Generic | C44: Exact | D44: [trường thcs tư thục gò vấp] | E44: S_THCS_GV_Generic
A45: THCS | B45: Generic | C45: Phrase | D45: "trường cấp 2 song ngữ" | E45: S_THCS_GV_Generic
A46: THCS | B46: HighIntent | C46: Exact | D46: [tuyển sinh lớp 6 trường tư] | E46: S_THCS_GV_HighIntent | F46: HOT
A47: THCS | B47: HighIntent | C47: Exact | D47: [học phí thcs song ngữ] | E47: S_THCS_GV_HighIntent
A48: THPT | B48: Generic | C48: Exact | D48: [trường thpt tư thục gò vấp] | E48: S_THPT_GV_Generic
...

Sheet 6. Meta Ads Chi Tiết
A1: KẾ HOẠCH META ADS – CẤU TRÚC + AUDIENCE + CREATIVE + PIXEL + GHL
A3: A. CẤU TRÚC TÀI KHOẢN META ADS (BỎ PHÚ NHUẬN)
A4: Campaign | B4: Objective | C4: Audience | D4: Creative | E4: Budget/tháng | F4: LP | G4: GHL Pipeline | H4: GTM/Pixel Events
A5: MN_GV_LeadGen | B5: Lead Generation | C5: Geo 5km MN GV | Age 25-40 | Interest Parenting | Lookalike 1-3% | D5: Video testi PH 15-30s + Carousel campus + Lead form | E5: =0.38*'1. Input'!B15*0.25/6 -> 1.3458333e+08 | F5: LP_MN_GV | G5: Pipeline MN | H5: Lead, ViewContent, CompleteRegistration
A6: MN_Tinh_LeadGen | B6: Lead Generation | C6: Geo Cần Giuộc (Tây Ninh) + Rạch Giá (An Giang) | Age 25-40 | D6: Video testi + Ảnh campus local + Lead form | E6: =0.38*'1. Input'!B15*0.12/6 -> 64600000 | F6: LP_MN_Tinh | G6: Pipeline MN | H6: Lead, ViewContent
A7: TH_GV_LeadGen | B7: Lead Generation | C7: Geo 8km TH GV | Age 28-45 | Lookalike PH TH | D7: Video lớp học + Carousel chương trình + Messenger | E7: =0.38*'1. Input'!B15*0.18/6 -> 96900000 | F7: LP_TH_GV | G7: Pipeline TH | H7: Lead, ViewContent
A8: TH_BT_LeadGen | B8: Lead Generation | C8: Geo 8km Bình Tân | Age 28-45 | D8: Video + Lead form | E8: =0.38*'1. Input'!B15*0.15/6 -> 80750000 | F8: LP_TH_BT | G8: Pipeline TH | H8: Lead
A9: TH_Tinh_LeadGen | B9: Lead Generation | C9: Geo Thái Sơn + Mekong Xanh | D9: Video local + Lead form | E9: =0.38*'1. Input'!B15*0.08/6 -> 43066667 | F9: LP_TH_Tinh | G9: Pipeline TH | H9: Lead
A10: THCS_GV_Conv | B10: Conversions | C10: Geo TP.HCM | Age 30-50 | Custom: Web 30d | D10: Video HS+GV + Testi 60s + Webinar ads | E10: =0.38*'1. Input'!B15*0.2/6 -> 1.0766667e+08 | F10: LP_THCS_GV | G10: Pipeline THCS | H10: Lead, WebinarReg, ViewContent
A11: THPT_GV_Conv | B11: Conversions | C11: Geo TP.HCM + miền Nam | Age 35-55 | Lookalike PH THPT | D11: Video đầu ra + Học bổng + Testi | E11: =0.38*'1. Input'!B15*0.2/6 -> 1.0766667e+08 | F11: LP_THPT_GV | G11: Pipeline THPT | H11: Lead, ScholarshipClick
A12: Remarketing_All | B12: Conversions | C12: PageView 7-30d | Exclude enrolled | Dynamic by cấp | D12: Carousel campus + ưu đãi + Countdown | E12: =0.12*'1. Input'!B15*0.5/6 -> 85000000 | F12: Dynamic | G12: Retarget tag | H12: Purchase, Lead
A14: B. PIXEL + CAPI + GTM SETUP
A15: Bước | B15: Hành động | C15: Chi tiết | D15: Tool | E15: Timeline | F15: Trạng thái
A16: 1 | B16: Cài Meta Pixel qua GTM | C16: Tạo tag Meta Pixel Base Code trong GTM → fire on All Pages | D16: GTM + Meta | E16: Ngày 1 | F16: ☐
A17: 2 | B17: Tạo Custom Events trong GTM | C17: form_submit, click_call, click_zalo, webinar_register, scholarship_click | D17: GTM | E17: Ngày 1 | F17: ☐
A18: 3 | B18: Cài Conversion API (CAPI) | C18: Server-side tracking qua GHL webhook → Meta CAPI endpoint | D18: GHL + Meta | E18: Ngày 2 | F18: ☐
A19: 4 | B19: Tạo Custom Conversions | C19: 4 events: Form MN, Form TH, Form THCS/THPT, Tour Scheduled | D19: Meta Events Manager | E19: Ngày 2 | F19: ☐
A20: 5 | B20: Verify domain | C20: Xác minh domain truongvietanh.com trong Business Manager | D20: Meta Business Suite | E20: Ngày 1 | F20: ☐
A21: 6 | B21: Tạo Audience Library | C21: 8 saved audiences (4 cấp × 2 geo) + Lookalike 1%/3%/5% + Custom 7d/14d/30d/60d | D21: Meta Ads Manager | E21: Ngày 2 | F21: ☐
A22: 7 | B22: Sync GHL → Meta | C22: Upload enrolled parents list → Exclusion | Monthly refresh | D22: GHL + Meta | E22: Tuần 2 | F22: ☐
A23: 8 | B23: Setup Birch cho Meta | C23: Kết nối Meta Ads → Birch | Tạo rules CPL, budget pacing | D23: Birch | E23: Ngày 3 | F23: ☐
A25: C. CREATIVE RESOURCE PLAN – PHÂN BỔ ẢNH/VIDEO CHO META ADS
A26: Campaign | B26: Loại Creative | C26: Số lượng | D26: Format | E26: Nội dung | F26: Nguồn ảnh/video | G26: Refresh cycle | H26: A/B Test | I26: Ghi chú
A27: MN_GV_LeadGen | B27: Video testimonial PH | C27: 3 | D27: 9:16 Reel 15-30s | E27: PH chia sẻ: "Con tôi vui khi đến trường" | F27: Quay tại campus, PH thật | G27: 3 tuần | H27: Test 3 PH khác nhau | I27: Hook 3s quan trọng nhất
A28: MN_GV_LeadGen | B28: Carousel campus | C28: 2 | D28: 1:1 1080x1080 | E28: 6 slides: Sân chơi, Phòng học, Bếp ăn, Camera, GV, Hoạt động | F28: Chụp tại campus GV | G28: 4 tuần | H28: Test order slides | I28: Ảnh thật, không stock
A29: MN_GV_LeadGen | B29: Lead Form ad | C29: 2 | D29: 1:1 1080x1080 | E29: Image + text: "Đăng ký tour MN Việt Anh" | Form prefill | F29: Thiết kế Canva | G29: 2 tuần | H29: Test benefit vs offer | I29: Form ngắn: Tên+SĐT+Cấp
A30: TH_GV_LeadGen | B30: Video "Nền tảng lớp 1" | C30: 2 | D30: 9:16 Reel 30-60s | E30: Lớp học thực tế, HS đọc TA, GV tương tác | F30: Quay tại TH GV | G30: 4 tuần | H30: Test 30s vs 60s | I30: Show HS thật đang học
A31: TH_GV_LeadGen | B31: Carousel chương trình | C31: 2 | D31: 1:1 1080x1080 | E31: 6 slides: Chương trình, TA, STEM, Ngoại khóa, Sĩ số, Tour | F31: Chụp + thiết kế | G31: 4 tuần | H31: Test headline | I31: Infographic style
A32: TH_BT_LeadGen | B32: Image + text local | C32: 3 | D32: 1:1 1080x1080 | E32: Ảnh campus BT + text "Trường tư song ngữ Bình Tân" | F32: Chụp tại campus BT | G32: 3 tuần | H32: Test 3 images | I32: Local feel quan trọng
A33: THCS_GV_LeadGen | B33: Video testi HS + GV | C33: 3 | D33: 9:16 Reel 30-60s | E33: HS THCS chia sẻ + GV chủ nhiệm nói về lộ trình | F33: Quay tại THCS GV | G33: 3 tuần | H33: Test HS vs GV focus | I33: Emotional storytelling
A34: THCS_GV_Webinar | B34: Video invite webinar | C34: 2 | D34: 9:16 Reel 15s | E34: Teaser: "Hội thảo chuyển cấp 5→6 – Miễn phí" | F34: Thiết kế motion | G34: 2 tuần | H34: Test countdown vs benefit | I34: Urgency + value
A35: THPT_GV_LeadGen | B35: Video "Lộ trình THPT" | C35: 3 | D35: 9:16 Reel 30-60s | E35: Alumni ĐH chia sẻ + BGH nói về đầu ra | F35: Quay tại THPT + ĐH | G35: 3 tuần | H35: Test alumni vs BGH | I35: Data-driven: % ĐH top
A36: THPT_HocBong | B36: Image học bổng | C36: 3 | D36: 1:1 1080x1080 | E36: "Học bổng lên đến 100% – Deadline [ngày]" | Bold design | F36: Thiết kế Canva/AI | G36: 2 tuần | H36: Test % vs giá trị tiền | I36: Deadline rõ ràng
A37: Retarget_7d_Hot | B37: Dynamic creative | C37: 4 | D37: 1:1 multi-format | E37: Testimonial + ưu đãi + countdown + campus | F37: Mix từ kho | G37: 2 tuần | H37: Auto by Meta | I37: DCO cho remarketing
A38: Brand_Awareness | B38: Brand video 15s | C38: 2 | D38: 16:9 + 9:16 | E38: Montage: 8 campus, HS vui, USP overlay, logo end | F38: Quay + edit pro | G38: 6 tuần | H38: Test 15s vs 30s | I38: CPM optimize
A41: D. DAILY OPERATIONS – META ADS HÀNG NGÀY
A42: Thời gian | B42: Công việc | C42: Chi tiết | D42: Tool | E42: KPI check | F42: Action nếu lệch | G42: Ai làm
A43: 8:00 | B43: Check delivery & spend | C43: Ads Manager → Campaign overview → Check pacing 24h | D43: Meta Ads Manager / Birch | E43: Spend vs daily target ±10% | F43: Overspend → lower budget | Underspend → check ad set | G43: Performance
A44: 8:15 | B44: Check CPL by campaign | C44: Filter last 3 days → Sort by CPL → Identify top/bottom | D44: Meta Ads Manager | E44: CPL < target kênh | F44: CPL > 150% target → pause ad set → review creative | G44: Performance
A45: 8:30 | B45: Check ad set learning phase | C45: Review ad sets: Learning, Active, Learning Limited | D45: Meta Ads Manager | E45: 50 conversions / 7 ngày | F45: Learning Limited → consolidate ad sets hoặc tăng budget | G45: Performance
...

Sheet 7. TikTok Ads Chi Tiết
A1: KẾ HOẠCH TIKTOK ADS – 100 VIDEO TESTIMONIAL + CẤU TRÚC + GTM
A3: A. CẤU TRÚC CAMPAIGN TIKTOK
A4: Campaign | B4: Objective | C4: Targeting | D4: Creative (từ kho 100 video) | E4: Budget/tháng | F4: KPI | G4: GTM Events | H4: Ghi chú
A5: Spark_Testi_MN | B5: Traffic/Lead | C5: Age 25-45 | Parenting | Geo HCM+Tỉnh | D5: Boost organic testi PH MN | Hook 3s | 15-30s | E5: =0.1*'1. Input'!B15*0.3/6 -> 42500000 | F5: CPV ≤ 2K | Engage ≥ 5% | G5: ViewContent, ClickLink | H5: Dùng 100 video có sẵn
A6: Spark_Testi_THPT | B6: Traffic/Lead | C6: Age 30-55 | Education | Geo HCM | D6: Boost testi HS THPT + GV | Hook 3s | E6: =0.1*'1. Input'!B15*0.25/6 -> 35416667 | F6: CPV ≤ 2.5K | Lead | G6: ViewContent, Lead | H6: Social proof
A7: InFeed_CampusTour | B7: Traffic | C7: Age 25-45 | Geo radius 10km | D7: Virtual tour video | Day-in-the-life | CTA tour | E7: =0.1*'1. Input'!B15*0.2/6 -> 28333333 | F7: CPL ≤ 90K | CTR ≥ 1.5% | G7: ViewContent, ClickLink | H7: Quay sẵn hoặc UGC
A8: LeadGen_Form | B8: Lead Gen | C8: Age 28-45 | School selection | Lookalike | D8: Video HS + Instant form: Tên+SĐT+Cấp | E8: =0.1*'1. Input'!B15*0.2/6 -> 28333333 | F8: CPL ≤ 80K | Form ≥ 3% | G8: Lead, FormSubmit | H8: Form → GHL auto
A9: TopView_Brand | B9: Reach | C9: Broad 25-50 HCM | 1 ngày | D9: Video 15s brand hệ thống | 8 cơ sở | E9: =0.1*'1. Input'!B15*0.05/6 -> 7083333.3 | F9: Reach ≥ 2M | CPM ≤ 50K | G9: Impression | H9: Chỉ 2-3 ngày peak
A11: B. TIKTOK PIXEL + GTM SETUP
A12: Bước | B12: Hành động | C12: Chi tiết | D12: Tool | E12: Timeline | F12: Trạng thái
A13: 1 | B13: Tạo TikTok Pixel | C13: Tạo pixel trong TikTok Ads Manager | D13: TikTok Ads | E13: Ngày 1 | F13: ☐
A14: 2 | B14: Cài qua GTM | C14: Tạo Custom HTML tag với TikTok Pixel base code → All Pages | D14: GTM | E14: Ngày 1 | F14: ☐
A15: 3 | B15: Tạo Event tags | C15: ViewContent (LP view), ClickButton (CTA), SubmitForm, CompleteRegistration | D15: GTM | E15: Ngày 1 | F15: ☐
A16: 4 | B16: Test với TikTok Pixel Helper | C16: Verify events firing đúng trên mỗi LP | D16: Chrome Extension | E16: Ngày 1 | F16: ☐
A17: 5 | B17: Tạo Custom Audiences | C17: Website visitors 7d/14d/30d + Video viewers 50%+ + Form submitters | D17: TikTok Ads | E17: Ngày 2 | F17: ☐
A18: 6 | B18: Tạo Lookalike | C18: Từ enrolled parents list + Form submitters | D18: TikTok Ads | E18: Tuần 2 | F18: ☐
A19: 7 | B19: Setup Birch cho TikTok | C19: Kết nối TikTok → Birch | Budget pacing rules | D19: Birch | E19: Ngày 3 | F19: ☐

Sheet 8. GoHighLevel Setup
A1: GOHIGHLEVEL – SETUP TỪ ĐẦU + CRM + AUTOMATION + SALES + ZALO
A3: A. SETUP TÀI KHOẢN GHL TỪ ĐẦU
A4: Bước | B4: Module | C4: Hành động chi tiết | D4: Kết quả cần có | E4: Timeline | F4: Trạng thái
A5: 1 | B5: Account | C5: Tạo sub-account cho Việt Anh | Timezone VN | Currency VND | D5: Account live | E5: Ngày 1 | F5: ☐
A6: 2 | B6: Custom Fields | C6: Tạo fields: Campus, Grade, Source Channel, Campaign ID, Campaign Name, Keyword Theme, Lead Status, Qualified Flag, Tour Date, Tour Attended, Application, Deposit, Enrollment | D6: Tất cả fields có | E6: Ngày 1 | F6: ☐
A7: 3 | B7: Pipelines | C7: Tạo 4 pipelines: MN, TH, THCS, THPT | Stages: New → Contacted → Qualified → Tour Booked → Tour Done → Offer → Enrolled → Lost | D7: 4 pipelines active | E7: Ngày 1 | F7: ☐
A8: 4 | B8: Tags | C8: Tạo tag system: src_google, src_meta, src_tiktok, src_zalo, src_organic, campus_gv, campus_bt, campus_tinh, grade_mn, grade_th, grade_thcs, grade_thpt, qualified, booked_tour, tour_attended, enrolled, lost | D8: Tags ready | E8: Ngày 1 | F8: ☐
A9: 5 | B9: Users & Teams | C9: Tạo users cho sales team | Assign theo campus | Round-robin rules | D9: Team assigned | E9: Ngày 1 | F9: ☐
A10: 6 | B10: Phone & SMS | C10: Setup Twilio / VN SMS provider | Verify phone numbers | SMS templates | D10: SMS working | E10: Ngày 2 | F10: ☐
A11: 7 | B11: Zalo OA | C11: Kết nối Zalo OA | Tạo 8 template messages | Auto-reply menu | D11: Zalo connected | E11: Ngày 2 | F11: ☐
A12: 8 | B12: Email | C12: Setup domain, DKIM, SPF | Email templates: Welcome, Tour reminder, Follow-up, Scholarship, Thank you | D12: Email verified | E12: Ngày 2 | F12: ☐
A13: 9 | B13: Calendar | C13: Tạo booking calendar cho 6 cơ sở (bỏ PN) | Availability slots | Auto SMS confirm | D13: Calendar live | E13: Ngày 2 | F13: ☐
A14: 10 | B14: Forms | C14: Tạo 8 forms (1/LP) | UTM auto-capture | Pipeline auto-assign | D14: Forms embedded | E14: Ngày 3 | F14: ☐
A15: 11 | B15: Landing Pages | C15: Build hoặc embed 8 LP trong GHL | Form + tracking + Zalo widget | D15: LPs live | E15: Ngày 3-5 | F15: ☐
A17: B. AUTOMATION WORKFLOWS
A18: Workflow | B18: Trigger | C18: Actions | D18: SLA | E18: Kết quả | F18: Timeline | G18: Trạng thái
A19: Auto-assign lead | B19: New contact created | C19: Round-robin assign theo campus + Push notification + SMS to sales | D19: < 5 phút | E19: Lead có owner ngay | F19: Ngày 3 | G19: ☐
A20: Welcome sequence | B20: New lead + src_google/meta/tiktok | C20: SMS welcome 30s + Zalo message 5 phút + Email brochure 1h | D20: Tự động | E20: Mọi lead được chào | F20: Ngày 3 | G20: ☐
A21: Nurture chưa tour | B21: Lead > 48h chưa book tour | C21: SMS Day 2 → Zalo Day 4 → Email Day 7 → Call task Day 10 | D21: 4 touchpoints | E21: Tăng Lead→Tour | F21: Ngày 4 | G21: ☐
A22: Tour reminder | B22: Appointment booked | C22: SMS 48h trước + Zalo 2h trước + Email confirm | D22: Auto | E22: Giảm no-show | F22: Ngày 4 | G22: ☐
A23: Post-tour follow-up | B23: Tour completed (status changed) | C23: Thank you SMS 2h + Offer email 24h + Call task 48h | D23: 3 touchpoints | E23: Tăng Tour→Enroll | F23: Ngày 4 | G23: ☐
A24: Lost re-engage | B24: Marked Lost > 30 ngày | C24: Monthly email + SMS promo | Re-enter pipeline nếu click | D24: Monthly | E24: Reactivation | F24: Tuần 2 | G24: ☐
A25: Webinar sequence | B25: Webinar registered | C25: Confirm email + SMS 24h + Zalo 2h + Post-webinar call 24h | D25: 4 touchpoints | E25: Tăng attend + tour | F25: Ngày 5 | G25: ☐
A26: Scholarship workflow | B26: Scholarship form submitted | C26: Auto email confirm + Assign to senior counselor + Task create | D26: Immediate | E26: THPT priority | F26: Ngày 5 | G26: ☐
A27: Webhook → Sheets | B27: Any status change (qualified/tour/enroll) | C27: Custom webhook → Middleware → Google Sheets → Birch reads | D27: Real-time | E27: Birch data sync | F27: Tuần 2 | G27: ☐
A29: C. CRM + SALES INTEGRATION
A30: Module | B30: Setup | C30: Mục đích | D30: Ai dùng | E30: Ghi chú
A31: Pipeline Dashboard | B31: Kanban view theo campus + cấp | C31: Theo dõi real-time | D31: Sales Manager | E31: Filter by campus
A32: Conversations | B32: Unified inbox: SMS + Zalo + Email + FB Messenger | C32: Tất cả kênh 1 chỗ | D32: Sales team | E32: Reply nhanh
A33: Opportunities | B33: Gắn giá trị = học phí năm 1 | Track close rate | C33: Forecast revenue | D33: Manager + BGH | E33: Dự báo doanh thu
A34: Reporting | B34: Lead by source, campaign, campus | Conversion funnel | SLA tracking | C34: Đo hiệu quả | D34: Marketing + Sales | E34: Auto weekly email
A35: Call tracking | B35: Ghi âm cuộc gọi + log duration + outcome | C35: QA + Training | D35: QA team | E35: Mystery call chấm điểm
A36: Review request | B36: Sau enrollment → auto gửi review link Google Business | C36: Tăng review organic | D36: Auto | E36: Giúp Local SEO
A38: D. GHL + BIRCH INTEGRATION CHI TIẾT
A39: # | B39: Bước | C39: Hành động | D39: Chi tiết kỹ thuật | E39: Kết quả cần có | F39: Tool | G39: Timeline | H39: Trạng thái
A40: 1 | B40: Webhook Setup | C40: Tạo webhook từ GHL → Google Sheets | D40: GHL Workflow → Custom Webhook → POST to Sheets API middleware | E40: Data sync real-time | F40: GHL + Apps Script | G40: Ngày 3 | H40: ☐
A41: 2 | B41: Middleware Build | C41: Xây middleware nhận webhook GHL | D41: Node.js/Apps Script → Parse payload → Write to Google Sheets | E41: Middleware running 24/7 | F41: Apps Script / Cloud Run | G41: Ngày 3-4 | H41: ☐
A42: 3 | B42: Sheet Structure | C42: Tạo Google Sheet cho Birch đọc | D42: Columns: Date, Contact ID, Campus, Grade, Source, Campaign, Status, Qualified, Tour, Enrolled | E42: Sheet ready for Birch | F42: Google Sheets | G42: Ngày 3 | H42: ☐
A43: 4 | B43: Birch Connect Sheet | C43: Kết nối Birch với Google Sheets | D43: Birch Settings → Data Sources → Google Sheets → Share sheet | E43: Birch reads GHL data | F43: Birch | G43: Ngày 4 | H43: ☐
A44: 5 | B44: Custom Metrics Birch | C44: Tạo metrics kết hợp ads + CRM | D44: Qualified Rate = Q.Leads/Total Leads | Tour Rate = Tours/Leads | CAC = Spend/Enrolled | E44: Birch shows CRM metrics | F44: Birch Custom Metrics | G44: Ngày 4 | H44: ☐
...

Sheet 9. GTM Tracking
A1: GOOGLE TAG MANAGER – TRACKING SETUP TOÀN BỘ KÊNH
A3: A. TAGS CẦN CÀI TRONG GTM
A4: Tag | B4: Type | C4: Platform | D4: Trigger | E4: Ghi chú | F4: Timeline | G4: Trạng thái
A5: GA4 Config | B5: GA4 Configuration | C5: Google Analytics | D5: All Pages | E5: GA4 property chính | F5: Ngày 1 | G5: ☐
A6: GA4 - form_submit | B6: GA4 Event | C6: Google Analytics | D6: Form submission (all LPs) | E6: Khi form được submit | F6: Ngày 1 | G6: ☐
A7: GA4 - click_call | B7: GA4 Event | C7: Google Analytics | D7: Click on tel: links | E7: Bấm gọi hotline | F7: Ngày 1 | G7: ☐
A8: GA4 - click_zalo | B8: GA4 Event | C8: Google Analytics | D8: Click on Zalo widget/link | E8: Bấm Zalo | F8: Ngày 1 | G8: ☐
A9: GA4 - webinar_register | B9: GA4 Event | C9: Google Analytics | D9: Webinar form submit | E9: Đăng ký webinar | F9: Ngày 1 | G9: ☐
A10: GA4 - scholarship_click | B10: GA4 Event | C10: Google Analytics | D10: Click scholarship CTA | E10: THPT scholarship | F10: Ngày 1 | G10: ☐
A11: Meta Pixel Base | B11: Custom HTML | C11: Meta | D11: All Pages | E11: Pixel ID + PageView event | F11: Ngày 1 | G11: ☐
A12: Meta - Lead | B12: Custom HTML | C12: Meta | D12: Form submission | E12: Conversion event cho Meta | F12: Ngày 1 | G12: ☐
A13: Meta - ViewContent | B13: Custom HTML | C13: Meta | D13: LP Page View | E13: Content view tracking | F13: Ngày 1 | G13: ☐
A14: Meta - CompleteRegistration | B14: Custom HTML | C14: Meta | D14: Thank you page view | E14: Tour/webinar confirmed | F14: Ngày 1 | G14: ☐
A15: TikTok Pixel Base | B15: Custom HTML | C15: TikTok | D15: All Pages | E15: Pixel ID + PageView | F15: Ngày 1 | G15: ☐
... A20: Zalo Pixel | B20: Custom HTML | C20: Zalo | D20: All Pages + Form | E20: Zalo Ads tracking | F20: Ngày 2 | G20: ☐
A22: B. TRIGGERS CẦN TẠO
A23: Trigger | B23: Type | C23: Condition | D23: Dùng cho tags | E23: Ghi chú
A24: All Pages | B24: Page View | C24: Mọi trang | D24: GA4, Meta, TikTok, Google Ads RMKT, Zalo | E24: Base trigger
A25: Form Submit - All | B25: Form Submission | C25: Form ID contains 'ghl' hoặc class | D25: GA4 form, Meta Lead, TikTok Submit, GG Ads Conv | E25: Tất cả form trên LP
A26: Click Call | B26: Click - Just Links | C26: Click URL contains 'tel:' | D26: GA4 click_call, Google Ads call conv | E26: Hotline click
A27: Click Zalo | B27: Click - Just Links | C27: Click URL contains 'zalo.me' | D27: GA4 click_zalo | E27: Zalo widget click
A28: Click CTA Button | B28: Click - All Elements | C28: CSS selector cho CTA buttons | D28: TikTok ClickButton | E28: Tour / tư vấn buttons
A29: Thank You Page | B29: Page View | C29: Page URL contains '/thank-you' hoặc '/cam-on' | D29: Meta CompleteReg, GA4 conversion | E29: Sau form submit
A30: Webinar Form | B30: Form Submission | C30: Form contains 'webinar' | D30: GA4 webinar_register | E30: Chỉ webinar forms
A31: Scholarship CTA | B31: Click - All Elements | C31: Element contains 'scholarship' / 'hoc-bong' | D31: GA4 scholarship_click | E31: THPT only

Sheet 10. Lịch Công Việc Marketer
A1: LỊCH CÔNG VIỆC MARKETER – HÀNG NGÀY / TUẦN / THÁNG / QUÝ / NĂM
A3: A. CÔNG VIỆC HÀNG NGÀY (MỖI NGÀY LÀM VIỆC)
A4: STT | B4: Kênh | C4: Công việc | D4: Chi tiết | E4: Thời gian | F4: Ai làm | G4: Checklist
A5: 1 | B5: Google Ads | C5: Kiểm tra spend vs budget | D5: Login Birch → check pacing alert | Nếu overspend → giảm | E5: 8:00-8:15 | F5: Performance | G5: ☐
